Workbook
Name _: #REF!
Name _: #REF!
Name _: #REF!
Name _: #REF!
Name _: #REF!
Name _?쨲?f: #REF!
Name _?쨲?f: #REF!
Name _?쨲?f: #REF!
Name _?쨲?f: #REF!
Name _?쨲?f: #REF!
Name __?쨲?f: #REF!
Name __?쨲?f: #REF!
Name __?쨲?f: #REF!
Name __?쨲?f: #REF!
Name __?쨲?f: #REF!
Name ___?쨲?f: #REF!
Name __________aof2: #REF!
Name _________aof2: #REF!
Name ________aof2: #REF!
Name _______aof2: #REF!
Name ______aof2: #REF!
Name _____aof2: #REF!
Name ____aof2: #REF!
Name ___aof2: #REF!
Name __aof2: #REF!
Name __bookmark_1: #REF!
Name _1: #REF!
Name _1_?쨲?f: #REF!
Name _2: #REF!
Name _3_piece_type_과_2_piece_type_선정: #REF!
Name _3D_Mesh_올_풀림_발생_검토: #REF!
Name _4면_단가공_Guide: #REF!
Name _5°_이상인_경우_P_L_구조: #REF!
Name _aof2: #REF!
Name √: "SQRT"
Name ▣_5°_미만인_경우_P_L_구조: #REF!
Name ▣_Battery_Cover_착탈감_Guide_2: #REF!
Name ▣_Battery_분리를_위한_공간_확보__빼기_홈: #REF!
Name ▣_Module_Assy’_선정: #REF!
Name A: #REF!
Name AAA: #REF!
Name ABS_도금_Key_Guide: #REF!
Name ABS_도금_Key_Guide_2: #REF!
Name Access_Button: "업체현황_카드발송_List"
Name Access_Button1: "업체현황_카드발송_List"
Name Access_Button2: "업체현황_카드발송_List"
Name Access_Button3: "카드발송_카드발송_List1"
Name Access_Button4: "업체현황_카드발송_List"
Name AccessDatabase: "C:\My Documents\SCD\업무연락안양식.mdb"
Name Acryl_Mold_Key_Guide: #REF!
Name Actuator_형상_및_Click감_확보: #REF!
Name AF_Camera_Key___Dome_조립_치수: #REF!
Name AF_Camera_Key_FPCB의_두께_Check: #REF!
Name AF_Camera_Key_FPCB의_두께_Check_2: #REF!
Name AF_Camera_Key_기능_사양에_따른_돌출량: #REF!
Name ahebf: #REF!
Name Air_gap_및_Air_path_구조: #REF!
Name Air_Path_체적_확보_여부_Check: #REF!
Name Air_Path_체적_확보_여부_Check_2: #REF!
Name Air_Path_체적_확보_여부를_Check: #REF!

Sheet Daily_BU설비데이터 
F1: =R2&"-"&R3&"-"&R4&" Optical Measurement" -> WINE-VDA129BLAC01- Optical Measurement
P2: • Cut. Model : | R2: WINE
P3: • Model : | R3: VDA129BLAC01
P4: • Event :
P5: • Date : | R5: 2026-
P6: • Measure M/C : | R6: CA-410
P7: • Measure Q'ty : | R7: =COUNTA(C20:C697)&"ea" -> 0ea
B9: No. | C9: 구분 | F9: RED | H9: GREEN | J9: BLUE | L9: 색재현율 | M9: White | P9: Black | Q9: CR | R9: GCS | S9: Uniformity | U9: CCT | V9: ADIM | X9: Color | Z9: HEX | AA9: Remark
C10: Lot ID | D10: FOG | E10: CAL | F10: X | G10: Y | H10: X | I10: Y | J10: X | K10: Y | M10: X | N10: Y | O10: Luminance | P10: Luminance | S10: White | T10: Black | V10: Hex | W10: Luminance | X10: X | Y10: Y
B11: Spec. Min | F11: =F12-F14 -> 0.61 | G11: =G12-G14 -> 0.321 | H11: =H12-H14 -> 0.262 | I11: =I12-I14 -> 0.617 | J11: =J12-J14 -> 0.12 | K11: =K12-K14 -> 0.03 | L11: 70.8 | O11: 900 | Q11: 1000 | S11: 80 | T11: 50
B12: Spec. Typ | F12: 0.64 | G12: 0.351 | H12: 0.292 | I12: 0.647 | J12: 0.15 | K12: 0.06 | M12: 0.293 | N12: 0.32 | U12: 7800
B13: Spec. Max | F13: =F12+F14 -> 0.67 | G13: =G12+G14 -> 0.381 | H13: =H12+H14 -> 0.322 | I13: =I12+I14 -> 0.677 | J13: =J12+J14 -> 0.18 | K13: =K12+K14 -> 0.09 | O13: 945 | R13: 0.005
B14: Spec. Tol. | F14: 0.03 | G14: 0.03 | H14: 0.03 | I14: 0.03 | J14: 0.03 | K14: 0.03
B15: Avg. | F15: =AVERAGE(F20:F697) -> #DIV/0! | G15: =AVERAGE(G20:G697) -> #DIV/0! | H15: =AVERAGE(H20:H697) -> #DIV/0! | I15: =AVERAGE(I20:I697) -> #DIV/0! | J15: =AVERAGE(J20:J697) -> #DIV/0! | K15: =AVERAGE(K20:K697) -> #DIV/0! | L15: =AVERAGE(L20:L697) -> 0 | M15: =AVERAGE(M20:M697) -> #DIV/0! | ... T15: =AVERAGE(T20:T697) -> #DIV/0! | U15: =AVERAGE(U20:U76) -> 2021.2824 | V15: =AVERAGE(V20:V76) -> 2021.2824 | W15: =AVERAGE(W20:W76) -> 2021.2824 | X15: =AVERAGE(X20:X76) -> #DIV/0! | Y15: =AVERAGE(Y20:Y76) -> #DIV/0! | Z15: =AVERAGE(Z20:Z76) -> 10395.442
B16: Shift | F16: =F15-F12 -> #DIV/0! | G16: =G15-G12 -> #DIV/0! | H16: =H15-H12 -> #DIV/0! | I16: =I15-I12 -> #DIV/0! | J16: =J15-J12 -> #DIV/0! | K16: =K15-K12 -> #DIV/0! | L16: =L15-L12 -> 0 | M16: =M15-M12 -> #DIV/0! | ... Z16: =Z15-Z12 -> 10395.442
B17: Min. | F17: =MIN(F20:F697) -> 0 | G17: =MIN(G20:G697) -> 0 | H17: =MIN(H20:H697) -> 0 | I17: =MIN(I20:I697) -> 0 | J17: =MIN(J20:J697) -> 0 | K17: =MIN(K20:K697) -> 0 | L17: =MIN(L20:L697) -> 0 | M17: =MIN(M20:M697) -> 0 | ... T17: =MIN(T20:T697) -> 0 | U17: =MIN(U20:U76) -> 2021.2824 | V17: =MIN(V20:V76) -> 2021.2824 | W17: =MIN(W20:W76) -> 2021.2824 | X17: =MIN(X20:X76) -> #DIV/0! | Y17: =MIN(Y20:Y76) -> #DIV/0! | Z17: =MIN(Z20:Z76) -> 10395.442
B18: Max. | F18: =MAX(F20:F697) -> 0 | G18: =MAX(G20:G697) -> 0 | H18: =MAX(H20:H697) -> 0 | I18: =MAX(I20:I697) -> 0 | J18: =MAX(J20:J697) -> 0 | K18: =MAX(K20:K697) -> 0 | L18: =MAX(L20:L697) -> 0 | M18: =MAX(M20:M697) -> 0 | ... T18: =MAX(T20:T697) -> 0 | U18: =MAX(U20:U76) -> 2021.2824 | V18: =MAX(V20:V76) -> 2021.2824 | W18: =MAX(W20:W76) -> 2021.2824 | X18: =MAX(X20:X76) -> #DIV/0! | Y18: =MAX(Y20:Y76) -> #DIV/0! | Z18: =MAX(Z20:Z76) -> 10395.442 | AY18: Spec 표기 해당 영역 측정 수 만큼 수정
B19: CPK | D19: BU_TSP_Judge | E19: LMK_Judge | F19: =(1-ABS(((F13+F11)/2)-AVERAGE(F20:F697))/((F13-F11)/2))*((F13-F11)/(STDEV(F20:F697)*6)) -> #DIV/0! | G19: =(1-ABS(((G13+G11)/2)-AVERAGE(G20:G697))/((G13-G11)/2))*((G13-G11)/(STDEV(G20:G697)*6)) -> #DIV/0! | H19: =(1-ABS(((H13+H11)/2)-AVERAGE(H20:H697))/((H13-H11)/2))*((H13-H11)/(STDEV(H20:H697)*6)) -> #DIV/0! | I19: =(1-ABS(((I13+I11)/2)-AVERAGE(I20:I697))/((I13-I11)/2))*((I13-I11)/(STDEV(I20:I697)*6)) -> #DIV/0! | J19: =(1-ABS(((J13+J11)/2)-AVERAGE(J20:J697))/((J13-J11)/2))*((J13-J11)/(STDEV(J20:J697)*6)) -> #DIV/0! | K19: =(1-ABS(((K13+K11)/2)-AVERAGE(K20:K697))/((K13-K11)/2))*((K13-K11)/(STDEV(K20:K697)*6)) -> #DIV/0! | L19: =((AVERAGE(L20:L697)-L11)/(3*STDEV(L20:L697))) -> #DIV/0! | M19: =(1-ABS(((M13+M11)/2)-AVERAGE(M20:M697))/((M13-M11)/2))*((M13-M11)/(STDEV(M20:M697)*6)) -> #DIV/0! | N19: =(1-ABS(((N13+N11)/2)-AVERAGE(N20:N697))/((N13-N11)/2))*((N13-N11)/(STDEV(N20:N697)*6)) -> #DIV/0! | O19: =((AVERAGE(O20:O697)-O11)/(3*STDEV(O20:O697))) -> #DIV/0! | P19: =(1-ABS(((P13+P11)/2)-AVERAGE(P20:P697))/((P13-P11)/2))*((P13-P11)/(STDEV(P20:P697)*6)) -> #DIV/0! | Q19: =((AVERAGE(Q20:Q697)-Q11)/(3*STDEV(Q20:Q697))) -> #DIV/0! | R19: =(R13-AVERAGE(R20:R697))/(3*STDEV(R20:R697)) -> -8.3013508e+13 | S19: =((AVERAGE(S20:S697)-S11)/(3*STDEV(S20:S697))) -> #DIV/0! | T19: =((AVERAGE(T20:T697)-T11)/(3*STDEV(T20:T697))) -> #DIV/0! | U19: =(1-ABS(((U13+U11)/2)-AVERAGE(U20:U697))/((U13-U11)/2))*((U13-U11)/(STDEV(U20:U697)*6)) -> #DIV/0! | V19: =(1-ABS(((V13+V11)/2)-AVERAGE(V20:V697))/((V13-V11)/2))*((V13-V11)/(STDEV(V20:V697)*6)) -> #DIV/0! | W19: =(1-ABS(((W13+W11)/2)-AVERAGE(W20:W697))/((W13-W11)/2))*((W13-W11)/(STDEV(W20:W697)*6)) -> #DIV/0! | X19: =(1-ABS(((X13+X11)/2)-AVERAGE(X20:X697))/((X13-X11)/2))*((X13-X11)/(STDEV(X20:X697)*6)) -> #DIV/0! | Y19: =(1-ABS(((Y13+Y11)/2)-AVERAGE(Y20:Y697))/((Y13-Y11)/2))*((Y13-Y11)/(STDEV(Y20:Y697)*6)) -> #DIV/0! | Z19: =(1-ABS(((Z13+Z11)/2)-AVERAGE(Z20:Z697))/((Z13-Z11)/2))*((Z13-Z11)/(STDEV(Z20:Z697)*6)) -> #DIV/0! | AY19: 색재현율 Spec | AZ19: 휘도 Spec | BA19: CR Spec | BB19: GCS Spec
B20: #1 | L20: =1/2*((F20*I20+H20*K20+J20*G20)-(G20*H20+I20*J20+K20*F20))/0.1582*100 -> 0 | Q20: =O20/P20 -> #DIV/0! | R20: =SQRT(POWER(M20-$M$12,2)+POWER(N20-$N$12,2)) -> 0.43387671 | U20: =(-449*((M20-0.332)/(N20-0.1858))^3)+(3525*((M20-0.332)/(N20-0.1858))^2)+(-6823.3*(M20-0.332)/(N20-0.1858))+5520.33 -> 2021.2824 | V20: =(-449*((N20-0.332)/(O20-0.1858))^3)+(3525*((N20-0.332)/(O20-0.1858))^2)+(-6823.3*(N20-0.332)/(O20-0.1858))+5520.33 -> 2021.2824 | W20: =(-449*((O20-0.332)/(P20-0.1858))^3)+(3525*((O20-0.332)/(P20-0.1858))^2)+(-6823.3*(O20-0.332)/(P20-0.1858))+5520.33 -> 2021.2824 | X20: =(-449*((P20-0.332)/(Q20-0.1858))^3)+(3525*((P20-0.332)/(Q20-0.1858))^2)+(-6823.3*(P20-0.332)/(Q20-0.1858))+5520.33 -> #DIV/0! | Y20: =(-449*((Q20-0.332)/(R20-0.1858))^3)+(3525*((Q20-0.332)/(R20-0.1858))^2)+(-6823.3*(Q20-0.332)/(R20-0.1858))+5520.33 -> #DIV/0! | Z20: =(-449*((R20-0.332)/(S20-0.1858))^3)+(3525*((R20-0.332)/(S20-0.1858))^2)+(-6823.3*(R20-0.332)/(S20-0.1858))+5520.33 -> 10395.442
B21: #2 | L21: =1/2*((F21*I21+H21*K21+J21*G21)-(G21*H21+I21*J21+K21*F21))/0.1582*100 -> 0 | Q21: =O21/P21 -> #DIV/0! | R21: =SQRT(POWER(M21-$M$12,2)+POWER(N21-$N$12,2)) -> 0.43387671 | U21: =(-449*((M21-0.332)/(N21-0.1858))^3)+(3525*((M21-0.332)/(N21-0.1858))^2)+(-6823.3*(M21-0.332)/(N21-0.1858))+5520.33 -> 2021.2824
B22: #3 | L22: =1/2*((F22*I22+H22*K22+J22*G22)-(G22*H22+I22*J22+K22*F22))/0.1582*100 -> 0 | Q22: =O22/P22 -> #DIV/0! | R22: =SQRT(POWER(M22-$M$12,2)+POWER(N22-$N$12,2)) -> 0.43387671 | U22: =(-449*((M22-0.332)/(N22-0.1858))^3)+(3525*((M22-0.332)/(N22-0.1858))^2)+(-6823.3*(M22-0.332)/(N22-0.1858))+5520.33 -> 2021.2824
B23: #4 | L23: =1/2*((F23*I23+H23*K23+J23*G23)-(G23*H23+I23*J23+K23*F23))/0.1582*100 -> 0 | Q23: =O23/P23 -> #DIV/0! | R23: =SQRT(POWER(M23-$M$12,2)+POWER(N23-$N$12,2)) -> 0.43387671 | U23: =(-449*((M23-0.332)/(N23-0.1858))^3)+(3525*((M23-0.332)/(N23-0.1858))^2)+(-6823.3*(M23-0.332)/(N23-0.1858))+5520.33 -> 2021.2824 | AY23: =$L$11 -> 70.8 | AZ23: =$O$11 -> 900 | BA23: =$Q$11 -> 1000 | BB23: =$R$13 -> 0.005
B24: #5 | L24: =1/2*((F24*I24+H24*K24+J24*G24)-(G24*H24+I24*J24+K24*F24))/0.1582*100 -> 0 | Q24: =O24/P24 -> #DIV/0! | R24: =SQRT(POWER(M24-$M$12,2)+POWER(N24-$N$12,2)) -> 0.43387671 | U24: =(-449*((M24-0.332)/(N24-0.1858))^3)+(3525*((M24-0.332)/(N24-0.1858))^2)+(-6823.3*(M24-0.332)/(N24-0.1858))+5520.33 -> 2021.2824 | AY24: =$L$11 -> 70.8 | AZ24: =$O$11 -> 900 | BA24: =$Q$11 -> 1000 | BB24: =$R$13 -> 0.005
B25: #6 | L25: =1/2*((F25*I25+H25*K25+J25*G25)-(G25*H25+I25*J25+K25*F25))/0.1582*100 -> 0 | Q25: =O25/P25 -> #DIV/0! | R25: =SQRT(POWER(M25-$M$12,2)+POWER(N25-$N$12,2)) -> 0.43387671 | U25: =(-449*((M25-0.332)/(N25-0.1858))^3)+(3525*((M25-0.332)/(N25-0.1858))^2)+(-6823.3*(M25-0.332)/(N25-0.1858))+5520.33 -> 2021.2824 | AY25: =$L$11 -> 70.8 | AZ25: =$O$11 -> 900 | BA25: =$Q$11 -> 1000 | BB25: =$R$13 -> 0.005
B26: #7 | L26: =1/2*((F26*I26+H26*K26+J26*G26)-(G26*H26+I26*J26+K26*F26))/0.1582*100 -> 0 | Q26: =O26/P26 -> #DIV/0! | R26: =SQRT(POWER(M26-$M$12,2)+POWER(N26-$N$12,2)) -> 0.43387671 | U26: =(-449*((M26-0.332)/(N26-0.1858))^3)+(3525*((M26-0.332)/(N26-0.1858))^2)+(-6823.3*(M26-0.332)/(N26-0.1858))+5520.33 -> 2021.2824 | AY26: =$L$11 -> 70.8 | AZ26: =$O$11 -> 900 | BA26: =$Q$11 -> 1000 | BB26: =$R$13 -> 0.005
B27: #8 | L27: =1/2*((F27*I27+H27*K27+J27*G27)-(G27*H27+I27*J27+K27*F27))/0.1582*100 -> 0 | Q27: =O27/P27 -> #DIV/0! | R27: =SQRT(POWER(M27-$M$12,2)+POWER(N27-$N$12,2)) -> 0.43387671 | U27: =(-449*((M27-0.332)/(N27-0.1858))^3)+(3525*((M27-0.332)/(N27-0.1858))^2)+(-6823.3*(M27-0.332)/(N27-0.1858))+5520.33 -> 2021.2824 | AY27: =$L$11 -> 70.8 | AZ27: =$O$11 -> 900 | BA27: =$Q$11 -> 1000 | BB27: =$R$13 -> 0.005
B28: #9 | L28: =1/2*((F28*I28+H28*K28+J28*G28)-(G28*H28+I28*J28+K28*F28))/0.1582*100 -> 0 | Q28: =O28/P28 -> #DIV/0! | R28: =SQRT(POWER(M28-$M$12,2)+POWER(N28-$N$12,2)) -> 0.43387671 | U28: =(-449*((M28-0.332)/(N28-0.1858))^3)+(3525*((M28-0.332)/(N28-0.1858))^2)+(-6823.3*(M28-0.332)/(N28-0.1858))+5520.33 -> 2021.2824 | AY28: =$L$11 -> 70.8 | AZ28: =$O$11 -> 900 | BA28: =$Q$11 -> 1000 | BB28: =$R$13 -> 0.005
B29: #10 | L29: =1/2*((F29*I29+H29*K29+J29*G29)-(G29*H29+I29*J29+K29*F29))/0.1582*100 -> 0 | Q29: =O29/P29 -> #DIV/0! | R29: =SQRT(POWER(M29-$M$12,2)+POWER(N29-$N$12,2)) -> 0.43387671 | U29: =(-449*((M29-0.332)/(N29-0.1858))^3)+(3525*((M29-0.332)/(N29-0.1858))^2)+(-6823.3*(M29-0.332)/(N29-0.1858))+5520.33 -> 2021.2824 | AY29: =$L$11 -> 70.8 | AZ29: =$O$11 -> 900 | BA29: =$Q$11 -> 1000 | BB29: =$R$13 -> 0.005
B30: #11 | L30: =1/2*((F30*I30+H30*K30+J30*G30)-(G30*H30+I30*J30+K30*F30))/0.1582*100 -> 0 | Q30: =O30/P30 -> #DIV/0! | R30: =SQRT(POWER(M30-$M$12,2)+POWER(N30-$N$12,2)) -> 0.43387671 | U30: =(-449*((M30-0.332)/(N30-0.1858))^3)+(3525*((M30-0.332)/(N30-0.1858))^2)+(-6823.3*(M30-0.332)/(N30-0.1858))+5520.33 -> 2021.2824 | AQ30: 0.61 | AR30: 0.321 | AY30: =$L$11 -> 70.8 | AZ30: =$O$11 -> 900 | BA30: =$Q$11 -> 1000 | BB30: =$R$13 -> 0.005
B31: #12 | L31: =1/2*((F31*I31+H31*K31+J31*G31)-(G31*H31+I31*J31+K31*F31))/0.1582*100 -> 0 | Q31: =O31/P31 -> #DIV/0! | R31: =SQRT(POWER(M31-$M$12,2)+POWER(N31-$N$12,2)) -> 0.43387671 | U31: =(-449*((M31-0.332)/(N31-0.1858))^3)+(3525*((M31-0.332)/(N31-0.1858))^2)+(-6823.3*(M31-0.332)/(N31-0.1858))+5520.33 -> 2021.2824 | AH31: 0.298 | AI31: 0.325 | AQ31: 0.61 | AR31: 0.381 | AY31: =$L$11 -> 70.8 | AZ31: =$O$11 -> 900 | BA31: =$Q$11 -> 1000 | BB31: =$R$13 -> 0.005
B32: #13 | L32: =1/2*((F32*I32+H32*K32+J32*G32)-(G32*H32+I32*J32+K32*F32))/0.1582*100 -> 0 | Q32: =O32/P32 -> #DIV/0! | R32: =SQRT(POWER(M32-$M$12,2)+POWER(N32-$N$12,2)) -> 0.43387671 | U32: =(-449*((M32-0.332)/(N32-0.1858))^3)+(3525*((M32-0.332)/(N32-0.1858))^2)+(-6823.3*(M32-0.332)/(N32-0.1858))+5520.33 -> 2021.2824 | AH32: 0.298 | AI32: 0.315 | AQ32: 0.67 | AR32: 0.381 | AY32: =$L$11 -> 70.8 | AZ32: =$O$11 -> 900 | BA32: =$Q$11 -> 1000 | BB32: =$R$13 -> 0.005
B33: #14 | L33: =1/2*((F33*I33+H33*K33+J33*G33)-(G33*H33+I33*J33+K33*F33))/0.1582*100 -> 0 | Q33: =O33/P33 -> #DIV/0! | R33: =SQRT(POWER(M33-$M$12,2)+POWER(N33-$N$12,2)) -> 0.43387671 | U33: =(-449*((M33-0.332)/(N33-0.1858))^3)+(3525*((M33-0.332)/(N33-0.1858))^2)+(-6823.3*(M33-0.332)/(N33-0.1858))+5520.33 -> 2021.2824 | AH33: 0.288 | AI33: 0.315 | AQ33: 0.67 | AR33: 0.321 | AY33: =$L$11 -> 70.8 | AZ33: =$O$11 -> 900 | BA33: =$Q$11 -> 1000 | BB33: =$R$13 -> 0.005
B34: #15 | L34: =1/2*((F34*I34+H34*K34+J34*G34)-(G34*H34+I34*J34+K34*F34))/0.1582*100 -> 0 | Q34: =O34/P34 -> #DIV/0! | R34: =SQRT(POWER(M34-$M$12,2)+POWER(N34-$N$12,2)) -> 0.43387671 | U34: =(-449*((M34-0.332)/(N34-0.1858))^3)+(3525*((M34-0.332)/(N34-0.1858))^2)+(-6823.3*(M34-0.332)/(N34-0.1858))+5520.33 -> 2021.2824 | AQ34: 0.61 | AR34: 0.321 | AY34: =$L$11 -> 70.8 | AZ34: =$O$11 -> 900 | BA34: =$Q$11 -> 1000 | BB34: =$R$13 -> 0.005
B35: #16 | L35: =1/2*((F35*I35+H35*K35+J35*G35)-(G35*H35+I35*J35+K35*F35))/0.1582*100 -> 0 | Q35: =O35/P35 -> #DIV/0! | R35: =SQRT(POWER(M35-$M$12,2)+POWER(N35-$N$12,2)) -> 0.43387671 | U35: =(-449*((M35-0.332)/(N35-0.1858))^3)+(3525*((M35-0.332)/(N35-0.1858))^2)+(-6823.3*(M35-0.332)/(N35-0.1858))+5520.33 -> 2021.2824 | AY35: =$L$11 -> 70.8 | AZ35: =$O$11 -> 900 | BA35: =$Q$11 -> 1000 | BB35: =$R$13 -> 0.005
B36: #17 | L36: =1/2*((F36*I36+H36*K36+J36*G36)-(G36*H36+I36*J36+K36*F36))/0.1582*100 -> 0 | Q36: =O36/P36 -> #DIV/0! | R36: =SQRT(POWER(M36-$M$12,2)+POWER(N36-$N$12,2)) -> 0.43387671 | U36: =(-449*((M36-0.332)/(N36-0.1858))^3)+(3525*((M36-0.332)/(N36-0.1858))^2)+(-6823.3*(M36-0.332)/(N36-0.1858))+5520.33 -> 2021.2824 | AY36: =$L$11 -> 70.8 | AZ36: =$O$11 -> 900 | BA36: =$Q$11 -> 1000 | BB36: =$R$13 -> 0.005
B37: #18 | L37: =1/2*((F37*I37+H37*K37+J37*G37)-(G37*H37+I37*J37+K37*F37))/0.1582*100 -> 0 | Q37: =O37/P37 -> #DIV/0! | R37: =SQRT(POWER(M37-$M$12,2)+POWER(N37-$N$12,2)) -> 0.43387671 | U37: =(-449*((M37-0.332)/(N37-0.1858))^3)+(3525*((M37-0.332)/(N37-0.1858))^2)+(-6823.3*(M37-0.332)/(N37-0.1858))+5520.33 -> 2021.2824 | AY37: =$L$11 -> 70.8 | AZ37: =$O$11 -> 900 | BA37: =$Q$11 -> 1000 | BB37: =$R$13 -> 0.005
B38: #19 | L38: =1/2*((F38*I38+H38*K38+J38*G38)-(G38*H38+I38*J38+K38*F38))/0.1582*100 -> 0 | Q38: =O38/P38 -> #DIV/0! | R38: =SQRT(POWER(M38-$M$12,2)+POWER(N38-$N$12,2)) -> 0.43387671 | U38: =(-449*((M38-0.332)/(N38-0.1858))^3)+(3525*((M38-0.332)/(N38-0.1858))^2)+(-6823.3*(M38-0.332)/(N38-0.1858))+5520.33 -> 2021.2824 | AY38: =$L$11 -> 70.8 | AZ38: =$O$11 -> 900 | BA38: =$Q$11 -> 1000 | BB38: =$R$13 -> 0.005
B39: #20 | L39: =1/2*((F39*I39+H39*K39+J39*G39)-(G39*H39+I39*J39+K39*F39))/0.1582*100 -> 0 | Q39: =O39/P39 -> #DIV/0! | R39: =SQRT(POWER(M39-$M$12,2)+POWER(N39-$N$12,2)) -> 0.43387671 | U39: =(-449*((M39-0.332)/(N39-0.1858))^3)+(3525*((M39-0.332)/(N39-0.1858))^2)+(-6823.3*(M39-0.332)/(N39-0.1858))+5520.33 -> 2021.2824 | AY39: =$L$11 -> 70.8 | AZ39: =$O$11 -> 900 | BA39: =$Q$11 -> 1000 | BB39: =$R$13 -> 0.005
B40: #21 | L40: =1/2*((F40*I40+H40*K40+J40*G40)-(G40*H40+I40*J40+K40*F40))/0.1582*100 -> 0 | Q40: =O40/P40 -> #DIV/0! | R40: =SQRT(POWER(M40-$M$12,2)+POWER(N40-$N$12,2)) -> 0.43387671 | U40: =(-449*((M40-0.332)/(N40-0.1858))^3)+(3525*((M40-0.332)/(N40-0.1858))^2)+(-6823.3*(M40-0.332)/(N40-0.1858))+5520.33 -> 2021.2824 | AY40: =$L$11 -> 70.8 | AZ40: =$O$11 -> 900 | BA40: =$Q$11 -> 1000 | BB40: =$R$13 -> 0.005
B41: #22 | L41: =1/2*((F41*I41+H41*K41+J41*G41)-(G41*H41+I41*J41+K41*F41))/0.1582*100 -> 0 | Q41: =O41/P41 -> #DIV/0! | R41: =SQRT(POWER(M41-$M$12,2)+POWER(N41-$N$12,2)) -> 0.43387671 | U41: =(-449*((M41-0.332)/(N41-0.1858))^3)+(3525*((M41-0.332)/(N41-0.1858))^2)+(-6823.3*(M41-0.332)/(N41-0.1858))+5520.33 -> 2021.2824 | AY41: =$L$11 -> 70.8 | AZ41: =$O$11 -> 900 | BA41: =$Q$11 -> 1000 | BB41: =$R$13 -> 0.005
...

Sheet 출하데이터_Vlookup
F1: =R2&"-"&R3&"-"&R4&" Optical Measurement" -> WINE-VDA129BLAC01- Optical Measurement
P2: • Cut. Model : | R2: WINE
P3: • Model : | R3: VDA129BLAC01
P4: • Event :
P5: • Date : | R5: 2026-
P6: • Measure M/C : | R6: CA-410
P7: • Measure Q'ty : | R7: =COUNTA(C20:C697)&"ea" -> 0ea
B9: No. | C9: 구분 | F9: RED | H9: GREEN | J9: BLUE | L9: 색재현율 | M9: White | P9: Black | Q9: CR | R9: GCS | S9: Uniformity | U9: CCT | V9: ADIM | X9: Color | Z9: HEX | AA9: Remark
C10: Lot ID | D10: FOG | E10: CAL | F10: X | G10: Y | H10: X | I10: Y | J10: X | K10: Y | M10: X | N10: Y | O10: Luminance | P10: Luminance | S10: White | T10: Black | V10: Hex | W10: Luminance | X10: X | Y10: Y
B11: Spec. Min | F11: =F12-F14 -> 0.61 | G11: =G12-G14 -> 0.321 | H11: =H12-H14 -> 0.262 | I11: =I12-I14 -> 0.617 | J11: =J12-J14 -> 0.12 | K11: =K12-K14 -> 0.03 | L11: 70.8 | O11: 900 | Q11: 1000 | S11: 80 | T11: 50
B12: Spec. Typ | F12: 0.64 | G12: 0.351 | H12: 0.292 | I12: 0.647 | J12: 0.15 | K12: 0.06 | M12: 0.293 | N12: 0.32 | U12: 7800
B13: Spec. Max | F13: =F12+F14 -> 0.67 | G13: =G12+G14 -> 0.381 | H13: =H12+H14 -> 0.322 | I13: =I12+I14 -> 0.677 | J13: =J12+J14 -> 0.18 | K13: =K12+K14 -> 0.09 | O13: 945 | R13: 0.005
B14: Spec. Tol. | F14: 0.03 | G14: 0.03 | H14: 0.03 | I14: 0.03 | J14: 0.03 | K14: 0.03
B15: Avg. | F15: =AVERAGE(F20:F697) -> #N/A | G15: =AVERAGE(G20:G697) -> #N/A | H15: =AVERAGE(H20:H697) -> #N/A | I15: =AVERAGE(I20:I697) -> #N/A | J15: =AVERAGE(J20:J697) -> #N/A | K15: =AVERAGE(K20:K697) -> #N/A | L15: =AVERAGE(L20:L697) -> #N/A | M15: =AVERAGE(M20:M697) -> #N/A | ... T15: =AVERAGE(T20:T697) -> #N/A | U15: =AVERAGE(U20:U76) -> #N/A | V15: =AVERAGE(V20:V76) -> #N/A | W15: =AVERAGE(W20:W76) -> #N/A | X15: =AVERAGE(X20:X76) -> #N/A | Y15: =AVERAGE(Y20:Y76) -> #N/A | Z15: =AVERAGE(Z20:Z76) -> #N/A
B16: Shift | F16: =F15-F12 -> #N/A | G16: =G15-G12 -> #N/A | H16: =H15-H12 -> #N/A | I16: =I15-I12 -> #N/A | J16: =J15-J12 -> #N/A | K16: =K15-K12 -> #N/A | L16: =L15-L12 -> #N/A | M16: =M15-M12 -> #N/A | ... Z16: =Z15-Z12 -> #N/A
B17: Min. | F17: =MIN(F20:F697) -> #N/A | G17: =MIN(G20:G697) -> #N/A | H17: =MIN(H20:H697) -> #N/A | I17: =MIN(I20:I697) -> #N/A | J17: =MIN(J20:J697) -> #N/A | K17: =MIN(K20:K697) -> #N/A | L17: =MIN(L20:L697) -> #N/A | M17: =MIN(M20:M697) -> #N/A | ... T17: =MIN(T20:T697) -> #N/A | U17: =MIN(U20:U76) -> #N/A | V17: =MIN(V20:V76) -> #N/A | W17: =MIN(W20:W76) -> #N/A | X17: =MIN(X20:X76) -> #N/A | Y17: =MIN(Y20:Y76) -> #N/A | Z17: =MIN(Z20:Z76) -> #N/A
B18: Max. | F18: =MAX(F20:F697) -> #N/A | G18: =MAX(G20:G697) -> #N/A | H18: =MAX(H20:H697) -> #N/A | I18: =MAX(I20:I697) -> #N/A | J18: =MAX(J20:J697) -> #N/A | K18: =MAX(K20:K697) -> #N/A | L18: =MAX(L20:L697) -> #N/A | M18: =MAX(M20:M697) -> #N/A | ... T18: =MAX(T20:T697) -> #N/A | U18: =MAX(U20:U76) -> #N/A | V18: =MAX(V20:V76) -> #N/A | W18: =MAX(W20:W76) -> #N/A | X18: =MAX(X20:X76) -> #N/A | Y18: =MAX(Y20:Y76) -> #N/A | Z18: =MAX(Z20:Z76) -> #N/A | AY18: Spec 표기 해당 영역 측정 수 만큼 수정
B19: CPK | D19: BU_TSP_Judge | E19: LMK_Judge | F19: =(1-ABS(((F13+F11)/2)-AVERAGE(F20:F697))/((F13-F11)/2))*((F13-F11)/(STDEV(F20:F697)*6)) -> #N/A | G19: =(1-ABS(((G13+G11)/2)-AVERAGE(G20:G697))/((G13-G11)/2))*((G13-G11)/(STDEV(G20:G697)*6)) -> #N/A | H19: =(1-ABS(((H13+H11)/2)-AVERAGE(H20:H697))/((H13-H11)/2))*((H13-H11)/(STDEV(H20:H697)*6)) -> #N/A | I19: =(1-ABS(((I13+I11)/2)-AVERAGE(I20:I697))/((I13-I11)/2))*((I13-I11)/(STDEV(I20:I697)*6)) -> #N/A | J19: =(1-ABS(((J13+J11)/2)-AVERAGE(J20:J697))/((J13-J11)/2))*((J13-J11)/(STDEV(J20:J697)*6)) -> #N/A | K19: =(1-ABS(((K13+K11)/2)-AVERAGE(K20:K697))/((K13-K11)/2))*((K13-K11)/(STDEV(K20:K697)*6)) -> #N/A | L19: =((AVERAGE(L20:L697)-L11)/(3*STDEV(L20:L697))) -> #N/A | M19: =(1-ABS(((M13+M11)/2)-AVERAGE(M20:M697))/((M13-M11)/2))*((M13-M11)/(STDEV(M20:M697)*6)) -> #N/A | N19: =(1-ABS(((N13+N11)/2)-AVERAGE(N20:N697))/((N13-N11)/2))*((N13-N11)/(STDEV(N20:N697)*6)) -> #N/A | O19: =((AVERAGE(O20:O697)-O11)/(3*STDEV(O20:O697))) -> #N/A | P19: =(1-ABS(((P13+P11)/2)-AVERAGE(P20:P697))/((P13-P11)/2))*((P13-P11)/(STDEV(P20:P697)*6)) -> #N/A | Q19: =((AVERAGE(Q20:Q697)-Q11)/(3*STDEV(Q20:Q697))) -> #N/A | R19: =(R13-AVERAGE(R20:R697))/(3*STDEV(R20:R697)) -> #N/A | S19: =((AVERAGE(S20:S697)-S11)/(3*STDEV(S20:S697))) -> #N/A | T19: =((AVERAGE(T20:T697)-T11)/(3*STDEV(T20:T697))) -> #N/A | U19: =(1-ABS(((U13+U11)/2)-AVERAGE(U20:U697))/((U13-U11)/2))*((U13-U11)/(STDEV(U20:U697)*6)) -> #N/A | V19: =(1-ABS(((V13+V11)/2)-AVERAGE(V20:V697))/((V13-V11)/2))*((V13-V11)/(STDEV(V20:V697)*6)) -> #N/A | W19: =(1-ABS(((W13+W11)/2)-AVERAGE(W20:W697))/((W13-W11)/2))*((W13-W11)/(STDEV(W20:W697)*6)) -> #N/A | X19: =(1-ABS(((X13+X11)/2)-AVERAGE(X20:X697))/((X13-X11)/2))*((X13-X11)/(STDEV(X20:X697)*6)) -> #N/A | Y19: =(1-ABS(((Y13+Y11)/2)-AVERAGE(Y20:Y697))/((Y13-Y11)/2))*((Y13-Y11)/(STDEV(Y20:Y697)*6)) -> #N/A | Z19: =(1-ABS(((Z13+Z11)/2)-AVERAGE(Z20:Z697))/((Z13-Z11)/2))*((Z13-Z11)/(STDEV(Z20:Z697)*6)) -> #N/A | AY19: 색재현율 Spec | AZ19: 휘도 Spec | BA19: CR Spec | BB19: GCS Spec
B20: #1 | F20: =VLOOKUP($C20,'Daily_BU설비데이터 '!$C$20:$T$1000,4,0) -> #N/A | G20: =VLOOKUP($C20,'Daily_BU설비데이터 '!$C$20:$T$1000,5,0) -> #N/A | H20: =VLOOKUP($C20,'Daily_BU설비데이터 '!$C$20:$T$1000,6,0) -> #N/A | I20: =VLOOKUP($C20,'Daily_BU설비데이터 '!$C$20:$T$1000,7,0) -> #N/A | J20: =VLOOKUP($C20,'Daily_BU설비데이터 '!$C$20:$T$1000,8,0) -> #N/A | K20: =VLOOKUP($C20,'Daily_BU설비데이터 '!$C$20:$T$1000,9,0) -> #N/A | L20: =1/2*((F20*I20+H20*K20+J20*G20)-(G20*H20+I20*J20+K20*F20))/0.1582*100 -> #N/A | M20: =VLOOKUP($C20,'Daily_BU설비데이터 '!$C$20:$T$1000,11,0) -> #N/A | N20: =VLOOKUP($C20,'Daily_BU설비데이터 '!$C$20:$T$1000,12,0) -> #N/A | O20: =VLOOKUP($C20,'Daily_BU설비데이터 '!$C$20:$T$1000,13,0) -> #N/A | P20: =VLOOKUP($C20,'Daily_BU설비데이터 '!$C$20:$T$1000,14,0) -> #N/A | Q20: =O20/P20 -> #N/A | R20: =SQRT(POWER(M20-$M$12,2)+POWER(N20-$N$12,2)) -> #N/A | S20: =VLOOKUP($C20,'Daily_BU설비데이터 '!$C$20:$T$1000,17,0) -> #N/A | T20: =VLOOKUP($C20,'Daily_BU설비데이터 '!$C$20:$T$1000,18,0) -> #N/A | U20: =(-449*((M20-0.332)/(N20-0.1858))^3)+(3525*((M20-0.332)/(N20-0.1858))^2)+(-6823.3*(M20-0.332)/(N20-0.1858))+5520.33 -> #N/A | V20: =(-449*((N20-0.332)/(O20-0.1858))^3)+(3525*((N20-0.332)/(O20-0.1858))^2)+(-6823.3*(N20-0.332)/(O20-0.1858))+5520.33 -> #N/A | W20: =(-449*((O20-0.332)/(P20-0.1858))^3)+(3525*((O20-0.332)/(P20-0.1858))^2)+(-6823.3*(O20-0.332)/(P20-0.1858))+5520.33 -> #N/A | X20: =(-449*((P20-0.332)/(Q20-0.1858))^3)+(3525*((P20-0.332)/(Q20-0.1858))^2)+(-6823.3*(P20-0.332)/(Q20-0.1858))+5520.33 -> #N/A | Y20: =(-449*((Q20-0.332)/(R20-0.1858))^3)+(3525*((Q20-0.332)/(R20-0.1858))^2)+(-6823.3*(Q20-0.332)/(R20-0.1858))+5520.33 -> #N/A | Z20: =(-449*((R20-0.332)/(S20-0.1858))^3)+(3525*((R20-0.332)/(S20-0.1858))^2)+(-6823.3*(R20-0.332)/(S20-0.1858))+5520.33 -> #N/A
B21: #2 | F21: =VLOOKUP($C21,'Daily_BU설비데이터 '!$C$20:$T$1000,4,0) -> #N/A | G21: =VLOOKUP($C21,'Daily_BU설비데이터 '!$C$20:$T$1000,5,0) -> #N/A | H21: =VLOOKUP($C21,'Daily_BU설비데이터 '!$C$20:$T$1000,6,0) -> #N/A | I21: =VLOOKUP($C21,'Daily_BU설비데이터 '!$C$20:$T$1000,7,0) -> #N/A | J21: =VLOOKUP($C21,'Daily_BU설비데이터 '!$C$20:$T$1000,8,0) -> #N/A | K21: =VLOOKUP($C21,'Daily_BU설비데이터 '!$C$20:$T$1000,9,0) -> #N/A | L21: =1/2*((F21*I21+H21*K21+J21*G21)-(G21*H21+I21*J21+K21*F21))/0.1582*100 -> #N/A | M21: =VLOOKUP($C21,'Daily_BU설비데이터 '!$C$20:$T$1000,11,0) -> #N/A | N21: =VLOOKUP($C21,'Daily_BU설비데이터 '!$C$20:$T$1000,12,0) -> #N/A | O21: =VLOOKUP($C21,'Daily_BU설비데이터 '!$C$20:$T$1000,13,0) -> #N/A | P21: =VLOOKUP($C21,'Daily_BU설비데이터 '!$C$20:$T$1000,14,0) -> #N/A | Q21: =O21/P21 -> #N/A | R21: =SQRT(POWER(M21-$M$12,2)+POWER(N21-$N$12,2)) -> #N/A | S21: =VLOOKUP($C21,'Daily_BU설비데이터 '!$C$20:$T$1000,17,0) -> #N/A | T21: =VLOOKUP($C21,'Daily_BU설비데이터 '!$C$20:$T$1000,18,0) -> #N/A | U21: =(-449*((M21-0.332)/(N21-0.1858))^3)+(3525*((M21-0.332)/(N21-0.1858))^2)+(-6823.3*(M21-0.332)/(N21-0.1858))+5520.33 -> #N/A
B22: #3 | F22: =VLOOKUP($C22,'Daily_BU설비데이터 '!$C$20:$T$1000,4,0) -> #N/A | G22: =VLOOKUP($C22,'Daily_BU설비데이터 '!$C$20:$T$1000,5,0) -> #N/A | H22: =VLOOKUP($C22,'Daily_BU설비데이터 '!$C$20:$T$1000,6,0) -> #N/A | I22: =VLOOKUP($C22,'Daily_BU설비데이터 '!$C$20:$T$1000,7,0) -> #N/A | J22: =VLOOKUP($C22,'Daily_BU설비데이터 '!$C$20:$T$1000,8,0) -> #N/A | K22: =VLOOKUP($C22,'Daily_BU설비데이터 '!$C$20:$T$1000,9,0) -> #N/A | L22: =1/2*((F22*I22+H22*K22+J22*G22)-(G22*H22+I22*J22+K22*F22))/0.1582*100 -> #N/A | M22: =VLOOKUP($C22,'Daily_BU설비데이터 '!$C$20:$T$1000,11,0) -> #N/A | N22: =VLOOKUP($C22,'Daily_BU설비데이터 '!$C$20:$T$1000,12,0) -> #N/A | O22: =VLOOKUP($C22,'Daily_BU설비데이터 '!$C$20:$T$1000,13,0) -> #N/A | P22: =VLOOKUP($C22,'Daily_BU설비데이터 '!$C$20:$T$1000,14,0) -> #N/A | Q22: =O22/P22 -> #N/A | R22: =SQRT(POWER(M22-$M$12,2)+POWER(N22-$N$12,2)) -> #N/A | S22: =VLOOKUP($C22,'Daily_BU설비데이터 '!$C$20:$T$1000,17,0) -> #N/A | T22: =VLOOKUP($C22,'Daily_BU설비데이터 '!$C$20:$T$1000,18,0) -> #N/A | U22: =(-449*((M22-0.332)/(N22-0.1858))^3)+(3525*((M22-0.332)/(N22-0.1858))^2)+(-6823.3*(M22-0.332)/(N22-0.1858))+5520.33 -> #N/A
B23: #4 | F23: =VLOOKUP($C23,'Daily_BU설비데이터 '!$C$20:$T$1000,4,0) -> #N/A | G23: =VLOOKUP($C23,'Daily_BU설비데이터 '!$C$20:$T$1000,5,0) -> #N/A | H23: =VLOOKUP($C23,'Daily_BU설비데이터 '!$C$20:$T$1000,6,0) -> #N/A | I23: =VLOOKUP($C23,'Daily_BU설비데이터 '!$C$20:$T$1000,7,0) -> #N/A | J23: =VLOOKUP($C23,'Daily_BU설비데이터 '!$C$20:$T$1000,8,0) -> #N/A | K23: =VLOOKUP($C23,'Daily_BU설비데이터 '!$C$20:$T$1000,9,0) -> #N/A | L23: =1/2*((F23*I23+H23*K23+J23*G23)-(G23*H23+I23*J23+K23*F23))/0.1582*100 -> #N/A | M23: =VLOOKUP($C23,'Daily_BU설비데이터 '!$C$20:$T$1000,11,0) -> #N/A | N23: =VLOOKUP($C23,'Daily_BU설비데이터 '!$C$20:$T$1000,12,0) -> #N/A | O23: =VLOOKUP($C23,'Daily_BU설비데이터 '!$C$20:$T$1000,13,0) -> #N/A | P23: =VLOOKUP($C23,'Daily_BU설비데이터 '!$C$20:$T$1000,14,0) -> #N/A | Q23: =O23/P23 -> #N/A | R23: =SQRT(POWER(M23-$M$12,2)+POWER(N23-$N$12,2)) -> #N/A | S23: =VLOOKUP($C23,'Daily_BU설비데이터 '!$C$20:$T$1000,17,0) -> #N/A | T23: =VLOOKUP($C23,'Daily_BU설비데이터 '!$C$20:$T$1000,18,0) -> #N/A | U23: =(-449*((M23-0.332)/(N23-0.1858))^3)+(3525*((M23-0.332)/(N23-0.1858))^2)+(-6823.3*(M23-0.332)/(N23-0.1858))+5520.33 -> #N/A | AY23: =$L$11 -> 70.8 | AZ23: =$O$11 -> 900 | BA23: =$Q$11 -> 1000 | BB23: =$R$13 -> 0.005
B24: #5 | F24: =VLOOKUP($C24,'Daily_BU설비데이터 '!$C$20:$T$1000,4,0) -> #N/A | G24: =VLOOKUP($C24,'Daily_BU설비데이터 '!$C$20:$T$1000,5,0) -> #N/A | H24: =VLOOKUP($C24,'Daily_BU설비데이터 '!$C$20:$T$1000,6,0) -> #N/A | I24: =VLOOKUP($C24,'Daily_BU설비데이터 '!$C$20:$T$1000,7,0) -> #N/A | J24: =VLOOKUP($C24,'Daily_BU설비데이터 '!$C$20:$T$1000,8,0) -> #N/A | K24: =VLOOKUP($C24,'Daily_BU설비데이터 '!$C$20:$T$1000,9,0) -> #N/A | L24: =1/2*((F24*I24+H24*K24+J24*G24)-(G24*H24+I24*J24+K24*F24))/0.1582*100 -> #N/A | M24: =VLOOKUP($C24,'Daily_BU설비데이터 '!$C$20:$T$1000,11,0) -> #N/A | N24: =VLOOKUP($C24,'Daily_BU설비데이터 '!$C$20:$T$1000,12,0) -> #N/A | O24: =VLOOKUP($C24,'Daily_BU설비데이터 '!$C$20:$T$1000,13,0) -> #N/A | P24: =VLOOKUP($C24,'Daily_BU설비데이터 '!$C$20:$T$1000,14,0) -> #N/A | Q24: =O24/P24 -> #N/A | R24: =SQRT(POWER(M24-$M$12,2)+POWER(N24-$N$12,2)) -> #N/A | S24: =VLOOKUP($C24,'Daily_BU설비데이터 '!$C$20:$T$1000,17,0) -> #N/A | T24: =VLOOKUP($C24,'Daily_BU설비데이터 '!$C$20:$T$1000,18,0) -> #N/A | U24: =(-449*((M24-0.332)/(N24-0.1858))^3)+(3525*((M24-0.332)/(N24-0.1858))^2)+(-6823.3*(M24-0.332)/(N24-0.1858))+5520.33 -> #N/A | AY24: =$L$11 -> 70.8 | AZ24: =$O$11 -> 900 | BA24: =$Q$11 -> 1000 | BB24: =$R$13 -> 0.005
B25: #6 | F25: =VLOOKUP($C25,'Daily_BU설비데이터 '!$C$20:$T$1000,4,0) -> #N/A | G25: =VLOOKUP($C25,'Daily_BU설비데이터 '!$C$20:$T$1000,5,0) -> #N/A | H25: =VLOOKUP($C25,'Daily_BU설비데이터 '!$C$20:$T$1000,6,0) -> #N/A | I25: =VLOOKUP($C25,'Daily_BU설비데이터 '!$C$20:$T$1000,7,0) -> #N/A | J25: =VLOOKUP($C25,'Daily_BU설비데이터 '!$C$20:$T$1000,8,0) -> #N/A | K25: =VLOOKUP($C25,'Daily_BU설비데이터 '!$C$20:$T$1000,9,0) -> #N/A | L25: =1/2*((F25*I25+H25*K25+J25*G25)-(G25*H25+I25*J25+K25*F25))/0.1582*100 -> #N/A | M25: =VLOOKUP($C25,'Daily_BU설비데이터 '!$C$20:$T$1000,11,0) -> #N/A | N25: =VLOOKUP($C25,'Daily_BU설비데이터 '!$C$20:$T$1000,12,0) -> #N/A | O25: =VLOOKUP($C25,'Daily_BU설비데이터 '!$C$20:$T$1000,13,0) -> #N/A | P25: =VLOOKUP($C25,'Daily_BU설비데이터 '!$C$20:$T$1000,14,0) -> #N/A | Q25: =O25/P25 -> #N/A | R25: =SQRT(POWER(M25-$M$12,2)+POWER(N25-$N$12,2)) -> #N/A | S25: =VLOOKUP($C25,'Daily_BU설비데이터 '!$C$20:$T$1000,17,0) -> #N/A | T25: =VLOOKUP($C25,'Daily_BU설비데이터 '!$C$20:$T$1000,18,0) -> #N/A | U25: =(-449*((M25-0.332)/(N25-0.1858))^3)+(3525*((M25-0.332)/(N25-0.1858))^2)+(-6823.3*(M25-0.332)/(N25-0.1858))+5520.33 -> #N/A | AY25: =$L$11 -> 70.8 | AZ25: =$O$11 -> 900 | BA25: =$Q$11 -> 1000 | BB25: =$R$13 -> 0.005
B26: #7 | F26: =VLOOKUP($C26,'Daily_BU설비데이터 '!$C$20:$T$1000,4,0) -> #N/A | G26: =VLOOKUP($C26,'Daily_BU설비데이터 '!$C$20:$T$1000,5,0) -> #N/A | H26: =VLOOKUP($C26,'Daily_BU설비데이터 '!$C$20:$T$1000,6,0) -> #N/A | I26: =VLOOKUP($C26,'Daily_BU설비데이터 '!$C$20:$T$1000,7,0) -> #N/A | J26: =VLOOKUP($C26,'Daily_BU설비데이터 '!$C$20:$T$1000,8,0) -> #N/A | K26: =VLOOKUP($C26,'Daily_BU설비데이터 '!$C$20:$T$1000,9,0) -> #N/A | L26: =1/2*((F26*I26+H26*K26+J26*G26)-(G26*H26+I26*J26+K26*F26))/0.1582*100 -> #N/A | M26: =VLOOKUP($C26,'Daily_BU설비데이터 '!$C$20:$T$1000,11,0) -> #N/A | N26: =VLOOKUP($C26,'Daily_BU설비데이터 '!$C$20:$T$1000,12,0) -> #N/A | O26: =VLOOKUP($C26,'Daily_BU설비데이터 '!$C$20:$T$1000,13,0) -> #N/A | P26: =VLOOKUP($C26,'Daily_BU설비데이터 '!$C$20:$T$1000,14,0) -> #N/A | Q26: =O26/P26 -> #N/A | R26: =SQRT(POWER(M26-$M$12,2)+POWER(N26-$N$12,2)) -> #N/A | S26: =VLOOKUP($C26,'Daily_BU설비데이터 '!$C$20:$T$1000,17,0) -> #N/A | T26: =VLOOKUP($C26,'Daily_BU설비데이터 '!$C$20:$T$1000,18,0) -> #N/A | U26: =(-449*((M26-0.332)/(N26-0.1858))^3)+(3525*((M26-0.332)/(N26-0.1858))^2)+(-6823.3*(M26-0.332)/(N26-0.1858))+5520.33 -> #N/A | AY26: =$L$11 -> 70.8 | AZ26: =$O$11 -> 900 | BA26: =$Q$11 -> 1000 | BB26: =$R$13 -> 0.005
B27: #8 | F27: =VLOOKUP($C27,'Daily_BU설비데이터 '!$C$20:$T$1000,4,0) -> #N/A | G27: =VLOOKUP($C27,'Daily_BU설비데이터 '!$C$20:$T$1000,5,0) -> #N/A | H27: =VLOOKUP($C27,'Daily_BU설비데이터 '!$C$20:$T$1000,6,0) -> #N/A | I27: =VLOOKUP($C27,'Daily_BU설비데이터 '!$C$20:$T$1000,7,0) -> #N/A | J27: =VLOOKUP($C27,'Daily_BU설비데이터 '!$C$20:$T$1000,8,0) -> #N/A | K27: =VLOOKUP($C27,'Daily_BU설비데이터 '!$C$20:$T$1000,9,0) -> #N/A | L27: =1/2*((F27*I27+H27*K27+J27*G27)-(G27*H27+I27*J27+K27*F27))/0.1582*100 -> #N/A | M27: =VLOOKUP($C27,'Daily_BU설비데이터 '!$C$20:$T$1000,11,0) -> #N/A | N27: =VLOOKUP($C27,'Daily_BU설비데이터 '!$C$20:$T$1000,12,0) -> #N/A | O27: =VLOOKUP($C27,'Daily_BU설비데이터 '!$C$20:$T$1000,13,0) -> #N/A | P27: =VLOOKUP($C27,'Daily_BU설비데이터 '!$C$20:$T$1000,14,0) -> #N/A | Q27: =O27/P27 -> #N/A | R27: =SQRT(POWER(M27-$M$12,2)+POWER(N27-$N$12,2)) -> #N/A | S27: =VLOOKUP($C27,'Daily_BU설비데이터 '!$C$20:$T$1000,17,0) -> #N/A | T27: =VLOOKUP($C27,'Daily_BU설비데이터 '!$C$20:$T$1000,18,0) -> #N/A | U27: =(-449*((M27-0.332)/(N27-0.1858))^3)+(3525*((M27-0.332)/(N27-0.1858))^2)+(-6823.3*(M27-0.332)/(N27-0.1858))+5520.33 -> #N/A | AY27: =$L$11 -> 70.8 | AZ27: =$O$11 -> 900 | BA27: =$Q$11 -> 1000 | BB27: =$R$13 -> 0.005
B28: #9 | F28: =VLOOKUP($C28,'Daily_BU설비데이터 '!$C$20:$T$1000,4,0) -> #N/A | G28: =VLOOKUP($C28,'Daily_BU설비데이터 '!$C$20:$T$1000,5,0) -> #N/A | H28: =VLOOKUP($C28,'Daily_BU설비데이터 '!$C$20:$T$1000,6,0) -> #N/A | I28: =VLOOKUP($C28,'Daily_BU설비데이터 '!$C$20:$T$1000,7,0) -> #N/A | J28: =VLOOKUP($C28,'Daily_BU설비데이터 '!$C$20:$T$1000,8,0) -> #N/A | K28: =VLOOKUP($C28,'Daily_BU설비데이터 '!$C$20:$T$1000,9,0) -> #N/A | L28: =1/2*((F28*I28+H28*K28+J28*G28)-(G28*H28+I28*J28+K28*F28))/0.1582*100 -> #N/A | M28: =VLOOKUP($C28,'Daily_BU설비데이터 '!$C$20:$T$1000,11,0) -> #N/A | N28: =VLOOKUP($C28,'Daily_BU설비데이터 '!$C$20:$T$1000,12,0) -> #N/A | O28: =VLOOKUP($C28,'Daily_BU설비데이터 '!$C$20:$T$1000,13,0) -> #N/A | P28: =VLOOKUP($C28,'Daily_BU설비데이터 '!$C$20:$T$1000,14,0) -> #N/A | Q28: =O28/P28 -> #N/A | R28: =SQRT(POWER(M28-$M$12,2)+POWER(N28-$N$12,2)) -> #N/A | S28: =VLOOKUP($C28,'Daily_BU설비데이터 '!$C$20:$T$1000,17,0) -> #N/A | T28: =VLOOKUP($C28,'Daily_BU설비데이터 '!$C$20:$T$1000,18,0) -> #N/A | U28: =(-449*((M28-0.332)/(N28-0.1858))^3)+(3525*((M28-0.332)/(N28-0.1858))^2)+(-6823.3*(M28-0.332)/(N28-0.1858))+5520.33 -> #N/A | AY28: =$L$11 -> 70.8 | AZ28: =$O$11 -> 900 | BA28: =$Q$11 -> 1000 | BB28: =$R$13 -> 0.005
B29: #10 | F29: =VLOOKUP($C29,'Daily_BU설비데이터 '!$C$20:$T$1000,4,0) -> #N/A | G29: =VLOOKUP($C29,'Daily_BU설비데이터 '!$C$20:$T$1000,5,0) -> #N/A | H29: =VLOOKUP($C29,'Daily_BU설비데이터 '!$C$20:$T$1000,6,0) -> #N/A | I29: =VLOOKUP($C29,'Daily_BU설비데이터 '!$C$20:$T$1000,7,0) -> #N/A | J29: =VLOOKUP($C29,'Daily_BU설비데이터 '!$C$20:$T$1000,8,0) -> #N/A | K29: =VLOOKUP($C29,'Daily_BU설비데이터 '!$C$20:$T$1000,9,0) -> #N/A | L29: =1/2*((F29*I29+H29*K29+J29*G29)-(G29*H29+I29*J29+K29*F29))/0.1582*100 -> #N/A | M29: =VLOOKUP($C29,'Daily_BU설비데이터 '!$C$20:$T$1000,11,0) -> #N/A | N29: =VLOOKUP($C29,'Daily_BU설비데이터 '!$C$20:$T$1000,12,0) -> #N/A | O29: =VLOOKUP($C29,'Daily_BU설비데이터 '!$C$20:$T$1000,13,0) -> #N/A | P29: =VLOOKUP($C29,'Daily_BU설비데이터 '!$C$20:$T$1000,14,0) -> #N/A | Q29: =O29/P29 -> #N/A | R29: =SQRT(POWER(M29-$M$12,2)+POWER(N29-$N$12,2)) -> #N/A | S29: =VLOOKUP($C29,'Daily_BU설비데이터 '!$C$20:$T$1000,17,0) -> #N/A | T29: =VLOOKUP($C29,'Daily_BU설비데이터 '!$C$20:$T$1000,18,0) -> #N/A | U29: =(-449*((M29-0.332)/(N29-0.1858))^3)+(3525*((M29-0.332)/(N29-0.1858))^2)+(-6823.3*(M29-0.332)/(N29-0.1858))+5520.33 -> #N/A | AY29: =$L$11 -> 70.8 | AZ29: =$O$11 -> 900 | BA29: =$Q$11 -> 1000 | BB29: =$R$13 -> 0.005
B30: #11 | F30: =VLOOKUP($C30,'Daily_BU설비데이터 '!$C$20:$T$1000,4,0) -> #N/A | G30: =VLOOKUP($C30,'Daily_BU설비데이터 '!$C$20:$T$1000,5,0) -> #N/A | H30: =VLOOKUP($C30,'Daily_BU설비데이터 '!$C$20:$T$1000,6,0) -> #N/A | I30: =VLOOKUP($C30,'Daily_BU설비데이터 '!$C$20:$T$1000,7,0) -> #N/A | J30: =VLOOKUP($C30,'Daily_BU설비데이터 '!$C$20:$T$1000,8,0) -> #N/A | K30: =VLOOKUP($C30,'Daily_BU설비데이터 '!$C$20:$T$1000,9,0) -> #N/A | L30: =1/2*((F30*I30+H30*K30+J30*G30)-(G30*H30+I30*J30+K30*F30))/0.1582*100 -> #N/A | M30: =VLOOKUP($C30,'Daily_BU설비데이터 '!$C$20:$T$1000,11,0) -> #N/A | N30: =VLOOKUP($C30,'Daily_BU설비데이터 '!$C$20:$T$1000,12,0) -> #N/A | O30: =VLOOKUP($C30,'Daily_BU설비데이터 '!$C$20:$T$1000,13,0) -> #N/A | P30: =VLOOKUP($C30,'Daily_BU설비데이터 '!$C$20:$T$1000,14,0) -> #N/A | Q30: =O30/P30 -> #N/A | R30: =SQRT(POWER(M30-$M$12,2)+POWER(N30-$N$12,2)) -> #N/A | S30: =VLOOKUP($C30,'Daily_BU설비데이터 '!$C$20:$T$1000,17,0) -> #N/A | T30: =VLOOKUP($C30,'Daily_BU설비데이터 '!$C$20:$T$1000,18,0) -> #N/A | U30: =(-449*((M30-0.332)/(N30-0.1858))^3)+(3525*((M30-0.332)/(N30-0.1858))^2)+(-6823.3*(M30-0.332)/(N30-0.1858))+5520.33 -> #N/A | AQ30: 0.61 | AR30: 0.321 | AY30: =$L$11 -> 70.8 | AZ30: =$O$11 -> 900 | BA30: =$Q$11 -> 1000 | BB30: =$R$13 -> 0.005
B31: #12 | F31: =VLOOKUP($C31,'Daily_BU설비데이터 '!$C$20:$T$1000,4,0) -> #N/A | G31: =VLOOKUP($C31,'Daily_BU설비데이터 '!$C$20:$T$1000,5,0) -> #N/A | H31: =VLOOKUP($C31,'Daily_BU설비데이터 '!$C$20:$T$1000,6,0) -> #N/A | I31: =VLOOKUP($C31,'Daily_BU설비데이터 '!$C$20:$T$1000,7,0) -> #N/A | J31: =VLOOKUP($C31,'Daily_BU설비데이터 '!$C$20:$T$1000,8,0) -> #N/A | K31: =VLOOKUP($C31,'Daily_BU설비데이터 '!$C$20:$T$1000,9,0) -> #N/A | L31: =1/2*((F31*I31+H31*K31+J31*G31)-(G31*H31+I31*J31+K31*F31))/0.1582*100 -> #N/A | M31: =VLOOKUP($C31,'Daily_BU설비데이터 '!$C$20:$T$1000,11,0) -> #N/A | N31: =VLOOKUP($C31,'Daily_BU설비데이터 '!$C$20:$T$1000,12,0) -> #N/A | O31: =VLOOKUP($C31,'Daily_BU설비데이터 '!$C$20:$T$1000,13,0) -> #N/A | P31: =VLOOKUP($C31,'Daily_BU설비데이터 '!$C$20:$T$1000,14,0) -> #N/A | Q31: =O31/P31 -> #N/A | R31: =SQRT(POWER(M31-$M$12,2)+POWER(N31-$N$12,2)) -> #N/A | S31: =VLOOKUP($C31,'Daily_BU설비데이터 '!$C$20:$T$1000,17,0) -> #N/A | T31: =VLOOKUP($C31,'Daily_BU설비데이터 '!$C$20:$T$1000,18,0) -> #N/A | U31: =(-449*((M31-0.332)/(N31-0.1858))^3)+(3525*((M31-0.332)/(N31-0.1858))^2)+(-6823.3*(M31-0.332)/(N31-0.1858))+5520.33 -> #N/A | AH31: 0.298 | AI31: 0.325 | AQ31: 0.61 | AR31: 0.381 | AY31: =$L$11 -> 70.8 | AZ31: =$O$11 -> 900 | BA31: =$Q$11 -> 1000 | BB31: =$R$13 -> 0.005
B32: #13 | F32: =VLOOKUP($C32,'Daily_BU설비데이터 '!$C$20:$T$1000,4,0) -> #N/A | G32: =VLOOKUP($C32,'Daily_BU설비데이터 '!$C$20:$T$1000,5,0) -> #N/A | H32: =VLOOKUP($C32,'Daily_BU설비데이터 '!$C$20:$T$1000,6,0) -> #N/A | I32: =VLOOKUP($C32,'Daily_BU설비데이터 '!$C$20:$T$1000,7,0) -> #N/A | J32: =VLOOKUP($C32,'Daily_BU설비데이터 '!$C$20:$T$1000,8,0) -> #N/A | K32: =VLOOKUP($C32,'Daily_BU설비데이터 '!$C$20:$T$1000,9,0) -> #N/A | L32: =1/2*((F32*I32+H32*K32+J32*G32)-(G32*H32+I32*J32+K32*F32))/0.1582*100 -> #N/A | M32: =VLOOKUP($C32,'Daily_BU설비데이터 '!$C$20:$T$1000,11,0) -> #N/A | N32: =VLOOKUP($C32,'Daily_BU설비데이터 '!$C$20:$T$1000,12,0) -> #N/A | O32: =VLOOKUP($C32,'Daily_BU설비데이터 '!$C$20:$T$1000,13,0) -> #N/A | P32: =VLOOKUP($C32,'Daily_BU설비데이터 '!$C$20:$T$1000,14,0) -> #N/A | Q32: =O32/P32 -> #N/A | R32: =SQRT(POWER(M32-$M$12,2)+POWER(N32-$N$12,2)) -> #N/A | S32: =VLOOKUP($C32,'Daily_BU설비데이터 '!$C$20:$T$1000,17,0) -> #N/A | T32: =VLOOKUP($C32,'Daily_BU설비데이터 '!$C$20:$T$1000,18,0) -> #N/A | U32: =(-449*((M32-0.332)/(N32-0.1858))^3)+(3525*((M32-0.332)/(N32-0.1858))^2)+(-6823.3*(M32-0.332)/(N32-0.1858))+5520.33 -> #N/A | AH32: 0.298 | AI32: 0.315 | AQ32: 0.67 | AR32: 0.381 | AY32: =$L$11 -> 70.8 | AZ32: =$O$11 -> 900 | BA32: =$Q$11 -> 1000 | BB32: =$R$13 -> 0.005
B33: #14 | F33: =VLOOKUP($C33,'Daily_BU설비데이터 '!$C$20:$T$1000,4,0) -> #N/A | G33: =VLOOKUP($C33,'Daily_BU설비데이터 '!$C$20:$T$1000,5,0) -> #N/A | H33: =VLOOKUP($C33,'Daily_BU설비데이터 '!$C$20:$T$1000,6,0) -> #N/A | I33: =VLOOKUP($C33,'Daily_BU설비데이터 '!$C$20:$T$1000,7,0) -> #N/A | J33: =VLOOKUP($C33,'Daily_BU설비데이터 '!$C$20:$T$1000,8,0) -> #N/A | K33: =VLOOKUP($C33,'Daily_BU설비데이터 '!$C$20:$T$1000,9,0) -> #N/A | L33: =1/2*((F33*I33+H33*K33+J33*G33)-(G33*H33+I33*J33+K33*F33))/0.1582*100 -> #N/A | M33: =VLOOKUP($C33,'Daily_BU설비데이터 '!$C$20:$T$1000,11,0) -> #N/A | N33: =VLOOKUP($C33,'Daily_BU설비데이터 '!$C$20:$T$1000,12,0) -> #N/A | O33: =VLOOKUP($C33,'Daily_BU설비데이터 '!$C$20:$T$1000,13,0) -> #N/A | P33: =VLOOKUP($C33,'Daily_BU설비데이터 '!$C$20:$T$1000,14,0) -> #N/A | Q33: =O33/P33 -> #N/A | R33: =SQRT(POWER(M33-$M$12,2)+POWER(N33-$N$12,2)) -> #N/A | S33: =VLOOKUP($C33,'Daily_BU설비데이터 '!$C$20:$T$1000,17,0) -> #N/A | T33: =VLOOKUP($C33,'Daily_BU설비데이터 '!$C$20:$T$1000,18,0) -> #N/A | U33: =(-449*((M33-0.332)/(N33-0.1858))^3)+(3525*((M33-0.332)/(N33-0.1858))^2)+(-6823.3*(M33-0.332)/(N33-0.1858))+5520.33 -> #N/A | AH33: 0.288 | AI33: 0.315 | AQ33: 0.67 | AR33: 0.321 | AY33: =$L$11 -> 70.8 | AZ33: =$O$11 -> 900 | BA33: =$Q$11 -> 1000 | BB33: =$R$13 -> 0.005
B34: #15 | F34: =VLOOKUP($C34,'Daily_BU설비데이터 '!$C$20:$T$1000,4,0) -> #N/A | G34: =VLOOKUP($C34,'Daily_BU설비데이터 '!$C$20:$T$1000,5,0) -> #N/A | H34: =VLOOKUP($C34,'Daily_BU설비데이터 '!$C$20:$T$1000,6,0) -> #N/A | I34: =VLOOKUP($C34,'Daily_BU설비데이터 '!$C$20:$T$1000,7,0) -> #N/A | J34: =VLOOKUP($C34,'Daily_BU설비데이터 '!$C$20:$T$1000,8,0) -> #N/A | K34: =VLOOKUP($C34,'Daily_BU설비데이터 '!$C$20:$T$1000,9,0) -> #N/A | L34: =1/2*((F34*I34+H34*K34+J34*G34)-(G34*H34+I34*J34+K34*F34))/0.1582*100 -> #N/A | M34: =VLOOKUP($C34,'Daily_BU설비데이터 '!$C$20:$T$1000,11,0) -> #N/A | N34: =VLOOKUP($C34,'Daily_BU설비데이터 '!$C$20:$T$1000,12,0) -> #N/A | O34: =VLOOKUP($C34,'Daily_BU설비데이터 '!$C$20:$T$1000,13,0) -> #N/A | P34: =VLOOKUP($C34,'Daily_BU설비데이터 '!$C$20:$T$1000,14,0) -> #N/A | Q34: =O34/P34 -> #N/A | R34: =SQRT(POWER(M34-$M$12,2)+POWER(N34-$N$12,2)) -> #N/A | S34: =VLOOKUP($C34,'Daily_BU설비데이터 '!$C$20:$T$1000,17,0) -> #N/A | T34: =VLOOKUP($C34,'Daily_BU설비데이터 '!$C$20:$T$1000,18,0) -> #N/A | U34: =(-449*((M34-0.332)/(N34-0.1858))^3)+(3525*((M34-0.332)/(N34-0.1858))^2)+(-6823.3*(M34-0.332)/(N34-0.1858))+5520.33 -> #N/A | AQ34: 0.61 | AR34: 0.321 | AY34: =$L$11 -> 70.8 | AZ34: =$O$11 -> 900 | BA34: =$Q$11 -> 1000 | BB34: =$R$13 -> 0.005
B35: #16 | F35: =VLOOKUP($C35,'Daily_BU설비데이터 '!$C$20:$T$1000,4,0) -> #N/A | G35: =VLOOKUP($C35,'Daily_BU설비데이터 '!$C$20:$T$1000,5,0) -> #N/A | H35: =VLOOKUP($C35,'Daily_BU설비데이터 '!$C$20:$T$1000,6,0) -> #N/A | I35: =VLOOKUP($C35,'Daily_BU설비데이터 '!$C$20:$T$1000,7,0) -> #N/A | J35: =VLOOKUP($C35,'Daily_BU설비데이터 '!$C$20:$T$1000,8,0) -> #N/A | K35: =VLOOKUP($C35,'Daily_BU설비데이터 '!$C$20:$T$1000,9,0) -> #N/A | L35: =1/2*((F35*I35+H35*K35+J35*G35)-(G35*H35+I35*J35+K35*F35))/0.1582*100 -> #N/A | M35: =VLOOKUP($C35,'Daily_BU설비데이터 '!$C$20:$T$1000,11,0) -> #N/A | N35: =VLOOKUP($C35,'Daily_BU설비데이터 '!$C$20:$T$1000,12,0) -> #N/A | O35: =VLOOKUP($C35,'Daily_BU설비데이터 '!$C$20:$T$1000,13,0) -> #N/A | P35: =VLOOKUP($C35,'Daily_BU설비데이터 '!$C$20:$T$1000,14,0) -> #N/A | Q35: =O35/P35 -> #N/A | R35: =SQRT(POWER(M35-$M$12,2)+POWER(N35-$N$12,2)) -> #N/A | S35: =VLOOKUP($C35,'Daily_BU설비데이터 '!$C$20:$T$1000,17,0) -> #N/A | T35: =VLOOKUP($C35,'Daily_BU설비데이터 '!$C$20:$T$1000,18,0) -> #N/A | U35: =(-449*((M35-0.332)/(N35-0.1858))^3)+(3525*((M35-0.332)/(N35-0.1858))^2)+(-6823.3*(M35-0.332)/(N35-0.1858))+5520.33 -> #N/A | AY35: =$L$11 -> 70.8 | AZ35: =$O$11 -> 900 | BA35: =$Q$11 -> 1000 | BB35: =$R$13 -> 0.005
B36: #17 | F36: =VLOOKUP($C36,'Daily_BU설비데이터 '!$C$20:$T$1000,4,0) -> #N/A | G36: =VLOOKUP($C36,'Daily_BU설비데이터 '!$C$20:$T$1000,5,0) -> #N/A | H36: =VLOOKUP($C36,'Daily_BU설비데이터 '!$C$20:$T$1000,6,0) -> #N/A | I36: =VLOOKUP($C36,'Daily_BU설비데이터 '!$C$20:$T$1000,7,0) -> #N/A | J36: =VLOOKUP($C36,'Daily_BU설비데이터 '!$C$20:$T$1000,8,0) -> #N/A | K36: =VLOOKUP($C36,'Daily_BU설비데이터 '!$C$20:$T$1000,9,0) -> #N/A | L36: =1/2*((F36*I36+H36*K36+J36*G36)-(G36*H36+I36*J36+K36*F36))/0.1582*100 -> #N/A | M36: =VLOOKUP($C36,'Daily_BU설비데이터 '!$C$20:$T$1000,11,0) -> #N/A | N36: =VLOOKUP($C36,'Daily_BU설비데이터 '!$C$20:$T$1000,12,0) -> #N/A | O36: =VLOOKUP($C36,'Daily_BU설비데이터 '!$C$20:$T$1000,13,0) -> #N/A | P36: =VLOOKUP($C36,'Daily_BU설비데이터 '!$C$20:$T$1000,14,0) -> #N/A | Q36: =O36/P36 -> #N/A | R36: =SQRT(POWER(M36-$M$12,2)+POWER(N36-$N$12,2)) -> #N/A | S36: =VLOOKUP($C36,'Daily_BU설비데이터 '!$C$20:$T$1000,17,0) -> #N/A | T36: =VLOOKUP($C36,'Daily_BU설비데이터 '!$C$20:$T$1000,18,0) -> #N/A | U36: =(-449*((M36-0.332)/(N36-0.1858))^3)+(3525*((M36-0.332)/(N36-0.1858))^2)+(-6823.3*(M36-0.332)/(N36-0.1858))+5520.33 -> #N/A | AY36: =$L$11 -> 70.8 | AZ36: =$O$11 -> 900 | BA36: =$Q$11 -> 1000 | BB36: =$R$13 -> 0.005
B37: #18 | F37: =VLOOKUP($C37,'Daily_BU설비데이터 '!$C$20:$T$1000,4,0) -> #N/A | G37: =VLOOKUP($C37,'Daily_BU설비데이터 '!$C$20:$T$1000,5,0) -> #N/A | H37: =VLOOKUP($C37,'Daily_BU설비데이터 '!$C$20:$T$1000,6,0) -> #N/A | I37: =VLOOKUP($C37,'Daily_BU설비데이터 '!$C$20:$T$1000,7,0) -> #N/A | J37: =VLOOKUP($C37,'Daily_BU설비데이터 '!$C$20:$T$1000,8,0) -> #N/A | K37: =VLOOKUP($C37,'Daily_BU설비데이터 '!$C$20:$T$1000,9,0) -> #N/A | L37: =1/2*((F37*I37+H37*K37+J37*G37)-(G37*H37+I37*J37+K37*F37))/0.1582*100 -> #N/A | M37: =VLOOKUP($C37,'Daily_BU설비데이터 '!$C$20:$T$1000,11,0) -> #N/A | N37: =VLOOKUP($C37,'Daily_BU설비데이터 '!$C$20:$T$1000,12,0) -> #N/A | O37: =VLOOKUP($C37,'Daily_BU설비데이터 '!$C$20:$T$1000,13,0) -> #N/A | P37: =VLOOKUP($C37,'Daily_BU설비데이터 '!$C$20:$T$1000,14,0) -> #N/A | Q37: =O37/P37 -> #N/A | R37: =SQRT(POWER(M37-$M$12,2)+POWER(N37-$N$12,2)) -> #N/A | S37: =VLOOKUP($C37,'Daily_BU설비데이터 '!$C$20:$T$1000,17,0) -> #N/A | T37: =VLOOKUP($C37,'Daily_BU설비데이터 '!$C$20:$T$1000,18,0) -> #N/A | U37: =(-449*((M37-0.332)/(N37-0.1858))^3)+(3525*((M37-0.332)/(N37-0.1858))^2)+(-6823.3*(M37-0.332)/(N37-0.1858))+5520.33 -> #N/A | AY37: =$L$11 -> 70.8 | AZ37: =$O$11 -> 900 | BA37: =$Q$11 -> 1000 | BB37: =$R$13 -> 0.005
B38: #19 | F38: =VLOOKUP($C38,'Daily_BU설비데이터 '!$C$20:$T$1000,4,0) -> #N/A | G38: =VLOOKUP($C38,'Daily_BU설비데이터 '!$C$20:$T$1000,5,0) -> #N/A | H38: =VLOOKUP($C38,'Daily_BU설비데이터 '!$C$20:$T$1000,6,0) -> #N/A | I38: =VLOOKUP($C38,'Daily_BU설비데이터 '!$C$20:$T$1000,7,0) -> #N/A | J38: =VLOOKUP($C38,'Daily_BU설비데이터 '!$C$20:$T$1000,8,0) -> #N/A | K38: =VLOOKUP($C38,'Daily_BU설비데이터 '!$C$20:$T$1000,9,0) -> #N/A | L38: =1/2*((F38*I38+H38*K38+J38*G38)-(G38*H38+I38*J38+K38*F38))/0.1582*100 -> #N/A | M38: =VLOOKUP($C38,'Daily_BU설비데이터 '!$C$20:$T$1000,11,0) -> #N/A | N38: =VLOOKUP($C38,'Daily_BU설비데이터 '!$C$20:$T$1000,12,0) -> #N/A | O38: =VLOOKUP($C38,'Daily_BU설비데이터 '!$C$20:$T$1000,13,0) -> #N/A | P38: =VLOOKUP($C38,'Daily_BU설비데이터 '!$C$20:$T$1000,14,0) -> #N/A | Q38: =O38/P38 -> #N/A | R38: =SQRT(POWER(M38-$M$12,2)+POWER(N38-$N$12,2)) -> #N/A | S38: =VLOOKUP($C38,'Daily_BU설비데이터 '!$C$20:$T$1000,17,0) -> #N/A | T38: =VLOOKUP($C38,'Daily_BU설비데이터 '!$C$20:$T$1000,18,0) -> #N/A | U38: =(-449*((M38-0.332)/(N38-0.1858))^3)+(3525*((M38-0.332)/(N38-0.1858))^2)+(-6823.3*(M38-0.332)/(N38-0.1858))+5520.33 -> #N/A | AY38: =$L$11 -> 70.8 | AZ38: =$O$11 -> 900 | BA38: =$Q$11 -> 1000 | BB38: =$R$13 -> 0.005
B39: #20 | F39: =VLOOKUP($C39,'Daily_BU설비데이터 '!$C$20:$T$1000,4,0) -> #N/A | G39: =VLOOKUP($C39,'Daily_BU설비데이터 '!$C$20:$T$1000,5,0) -> #N/A | H39: =VLOOKUP($C39,'Daily_BU설비데이터 '!$C$20:$T$1000,6,0) -> #N/A | I39: =VLOOKUP($C39,'Daily_BU설비데이터 '!$C$20:$T$1000,7,0) -> #N/A | J39: =VLOOKUP($C39,'Daily_BU설비데이터 '!$C$20:$T$1000,8,0) -> #N/A | K39: =VLOOKUP($C39,'Daily_BU설비데이터 '!$C$20:$T$1000,9,0) -> #N/A | L39: =1/2*((F39*I39+H39*K39+J39*G39)-(G39*H39+I39*J39+K39*F39))/0.1582*100 -> #N/A | M39: =VLOOKUP($C39,'Daily_BU설비데이터 '!$C$20:$T$1000,11,0) -> #N/A | N39: =VLOOKUP($C39,'Daily_BU설비데이터 '!$C$20:$T$1000,12,0) -> #N/A | O39: =VLOOKUP($C39,'Daily_BU설비데이터 '!$C$20:$T$1000,13,0) -> #N/A | P39: =VLOOKUP($C39,'Daily_BU설비데이터 '!$C$20:$T$1000,14,0) -> #N/A | Q39: =O39/P39 -> #N/A | R39: =SQRT(POWER(M39-$M$12,2)+POWER(N39-$N$12,2)) -> #N/A | S39: =VLOOKUP($C39,'Daily_BU설비데이터 '!$C$20:$T$1000,17,0) -> #N/A | T39: =VLOOKUP($C39,'Daily_BU설비데이터 '!$C$20:$T$1000,18,0) -> #N/A | U39: =(-449*((M39-0.332)/(N39-0.1858))^3)+(3525*((M39-0.332)/(N39-0.1858))^2)+(-6823.3*(M39-0.332)/(N39-0.1858))+5520.33 -> #N/A | AY39: =$L$11 -> 70.8 | AZ39: =$O$11 -> 900 | BA39: =$Q$11 -> 1000 | BB39: =$R$13 -> 0.005
B40: #21 | F40: =VLOOKUP($C40,'Daily_BU설비데이터 '!$C$20:$T$1000,4,0) -> #N/A | G40: =VLOOKUP($C40,'Daily_BU설비데이터 '!$C$20:$T$1000,5,0) -> #N/A | H40: =VLOOKUP($C40,'Daily_BU설비데이터 '!$C$20:$T$1000,6,0) -> #N/A | I40: =VLOOKUP($C40,'Daily_BU설비데이터 '!$C$20:$T$1000,7,0) -> #N/A | J40: =VLOOKUP($C40,'Daily_BU설비데이터 '!$C$20:$T$1000,8,0) -> #N/A | K40: =VLOOKUP($C40,'Daily_BU설비데이터 '!$C$20:$T$1000,9,0) -> #N/A | L40: =1/2*((F40*I40+H40*K40+J40*G40)-(G40*H40+I40*J40+K40*F40))/0.1582*100 -> #N/A | M40: =VLOOKUP($C40,'Daily_BU설비데이터 '!$C$20:$T$1000,11,0) -> #N/A | N40: =VLOOKUP($C40,'Daily_BU설비데이터 '!$C$20:$T$1000,12,0) -> #N/A | O40: =VLOOKUP($C40,'Daily_BU설비데이터 '!$C$20:$T$1000,13,0) -> #N/A | P40: =VLOOKUP($C40,'Daily_BU설비데이터 '!$C$20:$T$1000,14,0) -> #N/A | Q40: =O40/P40 -> #N/A | R40: =SQRT(POWER(M40-$M$12,2)+POWER(N40-$N$12,2)) -> #N/A | S40: =VLOOKUP($C40,'Daily_BU설비데이터 '!$C$20:$T$1000,17,0) -> #N/A | T40: =VLOOKUP($C40,'Daily_BU설비데이터 '!$C$20:$T$1000,18,0) -> #N/A | U40: =(-449*((M40-0.332)/(N40-0.1858))^3)+(3525*((M40-0.332)/(N40-0.1858))^2)+(-6823.3*(M40-0.332)/(N40-0.1858))+5520.33 -> #N/A | AY40: =$L$11 -> 70.8 | AZ40: =$O$11 -> 900 | BA40: =$Q$11 -> 1000 | BB40: =$R$13 -> 0.005
B41: #22 | F41: =VLOOKUP($C41,'Daily_BU설비데이터 '!$C$20:$T$1000,4,0) -> #N/A | G41: =VLOOKUP($C41,'Daily_BU설비데이터 '!$C$20:$T$1000,5,0) -> #N/A | H41: =VLOOKUP($C41,'Daily_BU설비데이터 '!$C$20:$T$1000,6,0) -> #N/A | I41: =VLOOKUP($C41,'Daily_BU설비데이터 '!$C$20:$T$1000,7,0) -> #N/A | J41: =VLOOKUP($C41,'Daily_BU설비데이터 '!$C$20:$T$1000,8,0) -> #N/A | K41: =VLOOKUP($C41,'Daily_BU설비데이터 '!$C$20:$T$1000,9,0) -> #N/A | L41: =1/2*((F41*I41+H41*K41+J41*G41)-(G41*H41+I41*J41+K41*F41))/0.1582*100 -> #N/A | M41: =VLOOKUP($C41,'Daily_BU설비데이터 '!$C$20:$T$1000,11,0) -> #N/A | N41: =VLOOKUP($C41,'Daily_BU설비데이터 '!$C$20:$T$1000,12,0) -> #N/A | O41: =VLOOKUP($C41,'Daily_BU설비데이터 '!$C$20:$T$1000,13,0) -> #N/A | P41: =VLOOKUP($C41,'Daily_BU설비데이터 '!$C$20:$T$1000,14,0) -> #N/A | Q41: =O41/P41 -> #N/A | R41: =SQRT(POWER(M41-$M$12,2)+POWER(N41-$N$12,2)) -> #N/A | S41: =VLOOKUP($C41,'Daily_BU설비데이터 '!$C$20:$T$1000,17,0) -> #N/A | T41: =VLOOKUP($C41,'Daily_BU설비데이터 '!$C$20:$T$1000,18,0) -> #N/A | U41: =(-449*((M41-0.332)/(N41-0.1858))^3)+(3525*((M41-0.332)/(N41-0.1858))^2)+(-6823.3*(M41-0.332)/(N41-0.1858))+5520.33 -> #N/A | AY41: =$L$11 -> 70.8 | AZ41: =$O$11 -> 900 | BA41: =$Q$11 -> 1000 | BB41: =$R$13 -> 0.005
...

Sheet 출하데이터_data
F1: =R2&"-"&R3&"-"&R4&" Optical Measurement" -> WINE-VDA129BLAC01- Optical Measurement
P2: • Cut. Model : | R2: WINE
P3: • Model : | R3: VDA129BLAC01
P4: • Event :
P5: • Date : | R5: 2026-
P6: • Measure M/C : | R6: CA-410
P7: • Measure Q'ty : | R7: =COUNTA(C20:C697)&"ea" -> 0ea
B9: No. | C9: 구분 | F9: RED | H9: GREEN | J9: BLUE | L9: 색재현율 | M9: White | P9: Black | Q9: CR | R9: GCS | S9: Uniformity | U9: CCT | V9: ADIM | X9: Color | Z9: HEX | AA9: Remark
C10: Lot ID | D10: FOG | E10: CAL | F10: X | G10: Y | H10: X | I10: Y | J10: X | K10: Y | M10: X | N10: Y | O10: Luminance | P10: Luminance | S10: White | T10: Black | V10: Hex | W10: Luminance | X10: X | Y10: Y
B11: Spec. Min | F11: =F12-F14 -> 0.61 | G11: =G12-G14 -> 0.321 | H11: =H12-H14 -> 0.262 | I11: =I12-I14 -> 0.617 | J11: =J12-J14 -> 0.12 | K11: =K12-K14 -> 0.03 | L11: 70.8 | O11: 900 | Q11: 1000 | S11: 80 | T11: 50
B12: Spec. Typ | F12: 0.64 | G12: 0.351 | H12: 0.292 | I12: 0.647 | J12: 0.15 | K12: 0.06 | M12: 0.293 | N12: 0.32 | U12: 7800
B13: Spec. Max | F13: =F12+F14 -> 0.67 | G13: =G12+G14 -> 0.381 | H13: =H12+H14 -> 0.322 | I13: =I12+I14 -> 0.677 | J13: =J12+J14 -> 0.18 | K13: =K12+K14 -> 0.09 | O13: 945 | R13: 0.005
B14: Spec. Tol. | F14: 0.03 | G14: 0.03 | H14: 0.03 | I14: 0.03 | J14: 0.03 | K14: 0.03
B15: Avg. | F15: =AVERAGE(F20:F697) -> #DIV/0! | G15: =AVERAGE(G20:G697) -> #DIV/0! | H15: =AVERAGE(H20:H697) -> #DIV/0! | I15: =AVERAGE(I20:I697) -> #DIV/0! | J15: =AVERAGE(J20:J697) -> #DIV/0! | K15: =AVERAGE(K20:K697) -> #DIV/0! | L15: =AVERAGE(L20:L697) -> 0 | M15: =AVERAGE(M20:M697) -> #DIV/0! | ... T15: =AVERAGE(T20:T697) -> #DIV/0! | U15: =AVERAGE(U20:U76) -> 2021.2824 | V15: =AVERAGE(V20:V76) -> 2021.2824 | W15: =AVERAGE(W20:W76) -> 2021.2824 | X15: =AVERAGE(X20:X76) -> #DIV/0! | Y15: =AVERAGE(Y20:Y76) -> #DIV/0! | Z15: =AVERAGE(Z20:Z76) -> 10395.442
B16: Shift | F16: =F15-F12 -> #DIV/0! | G16: =G15-G12 -> #DIV/0! | H16: =H15-H12 -> #DIV/0! | I16: =I15-I12 -> #DIV/0! | J16: =J15-J12 -> #DIV/0! | K16: =K15-K12 -> #DIV/0! | L16: =L15-L12 -> 0 | M16: =M15-M12 -> #DIV/0! | ... Z16: =Z15-Z12 -> 10395.442
B17: Min. | F17: =MIN(F20:F697) -> 0 | G17: =MIN(G20:G697) -> 0 | H17: =MIN(H20:H697) -> 0 | I17: =MIN(I20:I697) -> 0 | J17: =MIN(J20:J697) -> 0 | K17: =MIN(K20:K697) -> 0 | L17: =MIN(L20:L697) -> 0 | M17: =MIN(M20:M697) -> 0 | ... T17: =MIN(T20:T697) -> 0 | U17: =MIN(U20:U76) -> 2021.2824 | V17: =MIN(V20:V76) -> 2021.2824 | W17: =MIN(W20:W76) -> 2021.2824 | X17: =MIN(X20:X76) -> #DIV/0! | Y17: =MIN(Y20:Y76) -> #DIV/0! | Z17: =MIN(Z20:Z76) -> 10395.442
B18: Max. | F18: =MAX(F20:F697) -> 0 | G18: =MAX(G20:G697) -> 0 | H18: =MAX(H20:H697) -> 0 | I18: =MAX(I20:I697) -> 0 | J18: =MAX(J20:J697) -> 0 | K18: =MAX(K20:K697) -> 0 | L18: =MAX(L20:L697) -> 0 | M18: =MAX(M20:M697) -> 0 | ... T18: =MAX(T20:T697) -> 0 | U18: =MAX(U20:U76) -> 2021.2824 | V18: =MAX(V20:V76) -> 2021.2824 | W18: =MAX(W20:W76) -> 2021.2824 | X18: =MAX(X20:X76) -> #DIV/0! | Y18: =MAX(Y20:Y76) -> #DIV/0! | Z18: =MAX(Z20:Z76) -> 10395.442 | AY18: Spec 표기 해당 영역 측정 수 만큼 수정
B19: CPK | D19: BU_TSP_Judge | E19: LMK_Judge | F19: =(1-ABS(((F13+F11)/2)-AVERAGE(F20:F697))/((F13-F11)/2))*((F13-F11)/(STDEV(F20:F697)*6)) -> #DIV/0! | G19: =(1-ABS(((G13+G11)/2)-AVERAGE(G20:G697))/((G13-G11)/2))*((G13-G11)/(STDEV(G20:G697)*6)) -> #DIV/0! | H19: =(1-ABS(((H13+H11)/2)-AVERAGE(H20:H697))/((H13-H11)/2))*((H13-H11)/(STDEV(H20:H697)*6)) -> #DIV/0! | I19: =(1-ABS(((I13+I11)/2)-AVERAGE(I20:I697))/((I13-I11)/2))*((I13-I11)/(STDEV(I20:I697)*6)) -> #DIV/0! | J19: =(1-ABS(((J13+J11)/2)-AVERAGE(J20:J697))/((J13-J11)/2))*((J13-J11)/(STDEV(J20:J697)*6)) -> #DIV/0! | K19: =(1-ABS(((K13+K11)/2)-AVERAGE(K20:K697))/((K13-K11)/2))*((K13-K11)/(STDEV(K20:K697)*6)) -> #DIV/0! | L19: =((AVERAGE(L20:L697)-L11)/(3*STDEV(L20:L697))) -> #DIV/0! | M19: =(1-ABS(((M13+M11)/2)-AVERAGE(M20:M697))/((M13-M11)/2))*((M13-M11)/(STDEV(M20:M697)*6)) -> #DIV/0! | N19: =(1-ABS(((N13+N11)/2)-AVERAGE(N20:N697))/((N13-N11)/2))*((N13-N11)/(STDEV(N20:N697)*6)) -> #DIV/0! | O19: =((AVERAGE(O20:O697)-O11)/(3*STDEV(O20:O697))) -> #DIV/0! | P19: =(1-ABS(((P13+P11)/2)-AVERAGE(P20:P697))/((P13-P11)/2))*((P13-P11)/(STDEV(P20:P697)*6)) -> #DIV/0! | Q19: =((AVERAGE(Q20:Q697)-Q11)/(3*STDEV(Q20:Q697))) -> #DIV/0! | R19: =(R13-AVERAGE(R20:R697))/(3*STDEV(R20:R697)) -> -8.3013508e+13 | S19: =((AVERAGE(S20:S697)-S11)/(3*STDEV(S20:S697))) -> #DIV/0! | T19: =((AVERAGE(T20:T697)-T11)/(3*STDEV(T20:T697))) -> #DIV/0! | U19: =(1-ABS(((U13+U11)/2)-AVERAGE(U20:U697))/((U13-U11)/2))*((U13-U11)/(STDEV(U20:U697)*6)) -> #DIV/0! | V19: =(1-ABS(((V13+V11)/2)-AVERAGE(V20:V697))/((V13-V11)/2))*((V13-V11)/(STDEV(V20:V697)*6)) -> #DIV/0! | W19: =(1-ABS(((W13+W11)/2)-AVERAGE(W20:W697))/((W13-W11)/2))*((W13-W11)/(STDEV(W20:W697)*6)) -> #DIV/0! | X19: =(1-ABS(((X13+X11)/2)-AVERAGE(X20:X697))/((X13-X11)/2))*((X13-X11)/(STDEV(X20:X697)*6)) -> #DIV/0! | Y19: =(1-ABS(((Y13+Y11)/2)-AVERAGE(Y20:Y697))/((Y13-Y11)/2))*((Y13-Y11)/(STDEV(Y20:Y697)*6)) -> #DIV/0! | Z19: =(1-ABS(((Z13+Z11)/2)-AVERAGE(Z20:Z697))/((Z13-Z11)/2))*((Z13-Z11)/(STDEV(Z20:Z697)*6)) -> #DIV/0! | AY19: 색재현율 Spec | AZ19: 휘도 Spec | BA19: CR Spec | BB19: GCS Spec
B20: #1 | L20: =1/2*((F20*I20+H20*K20+J20*G20)-(G20*H20+I20*J20+K20*F20))/0.1582*100 -> 0 | Q20: =O20/P20 -> #DIV/0! | R20: =SQRT(POWER(M20-$M$12,2)+POWER(N20-$N$12,2)) -> 0.43387671 | U20: =(-449*((M20-0.332)/(N20-0.1858))^3)+(3525*((M20-0.332)/(N20-0.1858))^2)+(-6823.3*(M20-0.332)/(N20-0.1858))+5520.33 -> 2021.2824 | V20: =(-449*((N20-0.332)/(O20-0.1858))^3)+(3525*((N20-0.332)/(O20-0.1858))^2)+(-6823.3*(N20-0.332)/(O20-0.1858))+5520.33 -> 2021.2824 | W20: =(-449*((O20-0.332)/(P20-0.1858))^3)+(3525*((O20-0.332)/(P20-0.1858))^2)+(-6823.3*(O20-0.332)/(P20-0.1858))+5520.33 -> 2021.2824 | X20: =(-449*((P20-0.332)/(Q20-0.1858))^3)+(3525*((P20-0.332)/(Q20-0.1858))^2)+(-6823.3*(P20-0.332)/(Q20-0.1858))+5520.33 -> #DIV/0! | Y20: =(-449*((Q20-0.332)/(R20-0.1858))^3)+(3525*((Q20-0.332)/(R20-0.1858))^2)+(-6823.3*(Q20-0.332)/(R20-0.1858))+5520.33 -> #DIV/0! | Z20: =(-449*((R20-0.332)/(S20-0.1858))^3)+(3525*((R20-0.332)/(S20-0.1858))^2)+(-6823.3*(R20-0.332)/(S20-0.1858))+5520.33 -> 10395.442
B21: #2 | L21: =1/2*((F21*I21+H21*K21+J21*G21)-(G21*H21+I21*J21+K21*F21))/0.1582*100 -> 0 | Q21: =O21/P21 -> #DIV/0! | R21: =SQRT(POWER(M21-$M$12,2)+POWER(N21-$N$12,2)) -> 0.43387671 | U21: =(-449*((M21-0.332)/(N21-0.1858))^3)+(3525*((M21-0.332)/(N21-0.1858))^2)+(-6823.3*(M21-0.332)/(N21-0.1858))+5520.33 -> 2021.2824
B22: #3 | L22: =1/2*((F22*I22+H22*K22+J22*G22)-(G22*H22+I22*J22+K22*F22))/0.1582*100 -> 0 | Q22: =O22/P22 -> #DIV/0! | R22: =SQRT(POWER(M22-$M$12,2)+POWER(N22-$N$12,2)) -> 0.43387671 | U22: =(-449*((M22-0.332)/(N22-0.1858))^3)+(3525*((M22-0.332)/(N22-0.1858))^2)+(-6823.3*(M22-0.332)/(N22-0.1858))+5520.33 -> 2021.2824
B23: #4 | L23: =1/2*((F23*I23+H23*K23+J23*G23)-(G23*H23+I23*J23+K23*F23))/0.1582*100 -> 0 | Q23: =O23/P23 -> #DIV/0! | R23: =SQRT(POWER(M23-$M$12,2)+POWER(N23-$N$12,2)) -> 0.43387671 | U23: =(-449*((M23-0.332)/(N23-0.1858))^3)+(3525*((M23-0.332)/(N23-0.1858))^2)+(-6823.3*(M23-0.332)/(N23-0.1858))+5520.33 -> 2021.2824 | AY23: =$L$11 -> 70.8 | AZ23: =$O$11 -> 900 | BA23: =$Q$11 -> 1000 | BB23: =$R$13 -> 0.005
B24: #5 | L24: =1/2*((F24*I24+H24*K24+J24*G24)-(G24*H24+I24*J24+K24*F24))/0.1582*100 -> 0 | Q24: =O24/P24 -> #DIV/0! | R24: =SQRT(POWER(M24-$M$12,2)+POWER(N24-$N$12,2)) -> 0.43387671 | U24: =(-449*((M24-0.332)/(N24-0.1858))^3)+(3525*((M24-0.332)/(N24-0.1858))^2)+(-6823.3*(M24-0.332)/(N24-0.1858))+5520.33 -> 2021.2824 | AY24: =$L$11 -> 70.8 | AZ24: =$O$11 -> 900 | BA24: =$Q$11 -> 1000 | BB24: =$R$13 -> 0.005
B25: #6 | L25: =1/2*((F25*I25+H25*K25+J25*G25)-(G25*H25+I25*J25+K25*F25))/0.1582*100 -> 0 | Q25: =O25/P25 -> #DIV/0! | R25: =SQRT(POWER(M25-$M$12,2)+POWER(N25-$N$12,2)) -> 0.43387671 | U25: =(-449*((M25-0.332)/(N25-0.1858))^3)+(3525*((M25-0.332)/(N25-0.1858))^2)+(-6823.3*(M25-0.332)/(N25-0.1858))+5520.33 -> 2021.2824 | AY25: =$L$11 -> 70.8 | AZ25: =$O$11 -> 900 | BA25: =$Q$11 -> 1000 | BB25: =$R$13 -> 0.005
B26: #7 | L26: =1/2*((F26*I26+H26*K26+J26*G26)-(G26*H26+I26*J26+K26*F26))/0.1582*100 -> 0 | Q26: =O26/P26 -> #DIV/0! | R26: =SQRT(POWER(M26-$M$12,2)+POWER(N26-$N$12,2)) -> 0.43387671 | U26: =(-449*((M26-0.332)/(N26-0.1858))^3)+(3525*((M26-0.332)/(N26-0.1858))^2)+(-6823.3*(M26-0.332)/(N26-0.1858))+5520.33 -> 2021.2824 | AY26: =$L$11 -> 70.8 | AZ26: =$O$11 -> 900 | BA26: =$Q$11 -> 1000 | BB26: =$R$13 -> 0.005
B27: #8 | L27: =1/2*((F27*I27+H27*K27+J27*G27)-(G27*H27+I27*J27+K27*F27))/0.1582*100 -> 0 | Q27: =O27/P27 -> #DIV/0! | R27: =SQRT(POWER(M27-$M$12,2)+POWER(N27-$N$12,2)) -> 0.43387671 | U27: =(-449*((M27-0.332)/(N27-0.1858))^3)+(3525*((M27-0.332)/(N27-0.1858))^2)+(-6823.3*(M27-0.332)/(N27-0.1858))+5520.33 -> 2021.2824 | AY27: =$L$11 -> 70.8 | AZ27: =$O$11 -> 900 | BA27: =$Q$11 -> 1000 | BB27: =$R$13 -> 0.005
B28: #9 | L28: =1/2*((F28*I28+H28*K28+J28*G28)-(G28*H28+I28*J28+K28*F28))/0.1582*100 -> 0 | Q28: =O28/P28 -> #DIV/0! | R28: =SQRT(POWER(M28-$M$12,2)+POWER(N28-$N$12,2)) -> 0.43387671 | U28: =(-449*((M28-0.332)/(N28-0.1858))^3)+(3525*((M28-0.332)/(N28-0.1858))^2)+(-6823.3*(M28-0.332)/(N28-0.1858))+5520.33 -> 2021.2824 | AY28: =$L$11 -> 70.8 | AZ28: =$O$11 -> 900 | BA28: =$Q$11 -> 1000 | BB28: =$R$13 -> 0.005
B29: #10 | L29: =1/2*((F29*I29+H29*K29+J29*G29)-(G29*H29+I29*J29+K29*F29))/0.1582*100 -> 0 | Q29: =O29/P29 -> #DIV/0! | R29: =SQRT(POWER(M29-$M$12,2)+POWER(N29-$N$12,2)) -> 0.43387671 | U29: =(-449*((M29-0.332)/(N29-0.1858))^3)+(3525*((M29-0.332)/(N29-0.1858))^2)+(-6823.3*(M29-0.332)/(N29-0.1858))+5520.33 -> 2021.2824 | AY29: =$L$11 -> 70.8 | AZ29: =$O$11 -> 900 | BA29: =$Q$11 -> 1000 | BB29: =$R$13 -> 0.005
B30: #11 | L30: =1/2*((F30*I30+H30*K30+J30*G30)-(G30*H30+I30*J30+K30*F30))/0.1582*100 -> 0 | Q30: =O30/P30 -> #DIV/0! | R30: =SQRT(POWER(M30-$M$12,2)+POWER(N30-$N$12,2)) -> 0.43387671 | U30: =(-449*((M30-0.332)/(N30-0.1858))^3)+(3525*((M30-0.332)/(N30-0.1858))^2)+(-6823.3*(M30-0.332)/(N30-0.1858))+5520.33 -> 2021.2824 | AQ30: 0.61 | AR30: 0.321 | AY30: =$L$11 -> 70.8 | AZ30: =$O$11 -> 900 | BA30: =$Q$11 -> 1000 | BB30: =$R$13 -> 0.005
B31: #12 | L31: =1/2*((F31*I31+H31*K31+J31*G31)-(G31*H31+I31*J31+K31*F31))/0.1582*100 -> 0 | Q31: =O31/P31 -> #DIV/0! | R31: =SQRT(POWER(M31-$M$12,2)+POWER(N31-$N$12,2)) -> 0.43387671 | U31: =(-449*((M31-0.332)/(N31-0.1858))^3)+(3525*((M31-0.332)/(N31-0.1858))^2)+(-6823.3*(M31-0.332)/(N31-0.1858))+5520.33 -> 2021.2824 | AH31: 0.298 | AI31: 0.325 | AQ31: 0.61 | AR31: 0.381 | AY31: =$L$11 -> 70.8 | AZ31: =$O$11 -> 900 | BA31: =$Q$11 -> 1000 | BB31: =$R$13 -> 0.005
B32: #13 | L32: =1/2*((F32*I32+H32*K32+J32*G32)-(G32*H32+I32*J32+K32*F32))/0.1582*100 -> 0 | Q32: =O32/P32 -> #DIV/0! | R32: =SQRT(POWER(M32-$M$12,2)+POWER(N32-$N$12,2)) -> 0.43387671 | U32: =(-449*((M32-0.332)/(N32-0.1858))^3)+(3525*((M32-0.332)/(N32-0.1858))^2)+(-6823.3*(M32-0.332)/(N32-0.1858))+5520.33 -> 2021.2824 | AH32: 0.298 | AI32: 0.315 | AQ32: 0.67 | AR32: 0.381 | AY32: =$L$11 -> 70.8 | AZ32: =$O$11 -> 900 | BA32: =$Q$11 -> 1000 | BB32: =$R$13 -> 0.005
B33: #14 | L33: =1/2*((F33*I33+H33*K33+J33*G33)-(G33*H33+I33*J33+K33*F33))/0.1582*100 -> 0 | Q33: =O33/P33 -> #DIV/0! | R33: =SQRT(POWER(M33-$M$12,2)+POWER(N33-$N$12,2)) -> 0.43387671 | U33: =(-449*((M33-0.332)/(N33-0.1858))^3)+(3525*((M33-0.332)/(N33-0.1858))^2)+(-6823.3*(M33-0.332)/(N33-0.1858))+5520.33 -> 2021.2824 | AH33: 0.288 | AI33: 0.315 | AQ33: 0.67 | AR33: 0.321 | AY33: =$L$11 -> 70.8 | AZ33: =$O$11 -> 900 | BA33: =$Q$11 -> 1000 | BB33: =$R$13 -> 0.005
